Workbook

Sheet Règlement
A1: Plan de motivation commerciale RGZ, octobre 2026
A3: 1. Ce qu'on mesure
A4: Chaque agent a un objectif du jour : son objectif du mois divisé par le nombre de jours ouvrés. Les ventes validées sont saisies chaque soir et le tableau du jour est partagé le soir même ou le lendemain matin dans le groupe de l'équipe.
A5: En fin de mois, on regarde le taux de réalisation (TRO) : ventes validées du mois divisées par l'objectif du mois, B2C et B2B confondus.
A6: Seules les ventes validées par Celtiis comptent. Une vente résiliée ou rejetée dans le mois est retirée du compteur.
A8: 2. Ce que gagne un agent chaque jour
A9: Journée réussie : 200 FCFA chaque jour ouvré où l'agent atteint ou dépasse son objectif du jour. Un objectif de 1,75 vente par jour demande donc 2 ventes ce jour-là.
A10: Champion du jour : 1 000 FCFA à l'agent qui a le meilleur taux de réalisation de la journée, à condition d'avoir atteint son objectif du jour. Son nom est annoncé avec le tableau du jour.
A12: 3. Ce que gagne un agent en fin de mois
A13: TRO de 80 à 99 % : palier Engagé, 5 000 FCFA
A14: TRO de 100 à 119 % : palier Objectif, 12 500 FCFA
A15: TRO de 120 % et plus : palier Champion, 20 000 FCFA
... A35: Source des objectifs : onglet OBJECTIFS TRACKING du fichier Performance_partenaire_2026.xlsx (1 487 ventes). Réalisé de septembre : onglet POINT PAR LOGIN du même fichier.

Sheet Paramètres
A1: Paramètres du plan
A2: Cellules jaunes = valeurs modifiables. Tout le reste du fichier se recalcule à partir d'ici.
A3: Calendrier d'octobre
A4: Jour | B4: 1 | C4: 2 | D4: 3 | E4: 4 | F4: 5 | G4: 6 | H4: 7 | I4: 8 | J4: 9 | K4: 10 | L4: 11 | M4: 12 | N4: 13 | O4: 14 | P4: 15 | Q4: 16 | R4: 17 | S4: 18 | T4: 19 | U4: 20 | V4: 21 | W4: 22 | X4: 23 | Y4: 24 | Z4: 25 | AA4: 26 | AB4: 27 | AC4: 28 | AD4: 29 | AE4: 30 | AF4: 31
A5: Date | B5: 46296 | C5: 46297 | D5: 46298 | E5: 46299 | F5: 46300 | G5: 46301 | H5: 46302 | I5: 46303 | J5: 46304 | K5: 46305 | L5: 46306 | M5: 46307 | N5: 46308 | O5: 46309 | P5: 46310 | Q5: 46311 | R5: 46312 | S5: 46313 | T5: 46314 | U5: 46315 | V5: 46316 | W5: 46317 | X5: 46318 | Y5: 46319 | Z5: 46320 | AA5: 46321 | AB5: 46322 | AC5: 46323 | AD5: 46324 | AE5: 46325 | AF5: 46326
A6: Jour de la semaine | B6: jeu | C6: ven | D6: sam | E6: dim | F6: lun | G6: mar | H6: mer | I6: jeu | J6: ven | K6: sam | L6: dim | M6: lun | N6: mar | O6: mer | P6: jeu | Q6: ven | R6: sam | S6: dim | T6: lun | U6: mar | V6: mer | W6: jeu | X6: ven | Y6: sam | Z6: dim | AA6: lun | AB6: mar | AC6: mer | AD6: jeu | AE6: ven | AF6: sam
A7: Ouvré (1 = oui, 0 = non) | B7: 1 | C7: 1 | D7: 0 | E7: 0 | F7: 1 | G7: 1 | H7: 1 | I7: 1 | J7: 1 | K7: 0 | L7: 0 | M7: 1 | N7: 1 | O7: 1 | P7: 1 | Q7: 1 | R7: 0 | S7: 0 | T7: 1 | U7: 1 | V7: 1 | W7: 1 | X7: 1 | Y7: 0 | Z7: 0 | AA7: 1 | AB7: 1 | AC7: 1 | AD7: 1 | AE7: 1 | AF7: 0
A9: Total jours ouvrés du mois | B9: =SUM(B7:AF7) -> 22
A10: Dernier jour saisi (1 à 31) | B10: 1
A11: Jours ouvrés écoulés | B11: =SUMPRODUCT((B4:AF4<=B10)*B7:AF7) -> 1
A13: Agents : paliers de fin de mois (TRO)
A14: Palier | B14: Seuil TRO | C14: Prime (FCFA)
A15: Aucun | B15: 0 | C15: 0
A16: Engagé | B16: 0.8 | C16: 5000
A17: Objectif | B17: 1 | C17: 12500
A18: Champion | B18: 1.2 | C18: 20000
A20: Prime journée réussie (par jour ouvré) | C20: 200
A21: Prime champion du jour | C21: 1000
A22: Bonus objectif B2B atteint (fin de mois) | C22: 5000
A24: Superviseurs : paliers de fin de mois (TRO équipe)
A25: Palier | B25: Seuil TRO | C25: Prime (FCFA)
A26: Aucun | B26: 0 | C26: 0
A27: Bronze | B27: 0.9 | C27: 15000
A28: Argent | B28: 1 | C28: 30000
A29: Or | B29: 1.1 | C29: 50000
A31: Seuil pour compter un agent comme actif | C31: 0.8
A32: Taux d'activation minimum de l'équipe | C32: 0.6
A33: Prime superviseur par journée équipe réussie | C33: 500
A34: Trophée équipe du mois (enveloppe) | C34: 50000
A35: TRO minimum pour le trophée | C35: 1
A37: Commissions one-shot (pour le calcul de marge)
A38: Commission par vente B2C | C38: 10000 | D38: Source : fichier Performance_partenaire_2026, colonnes ONE_SHOT (12 470 000 / 1 247 B2C ; 2 880 000 / 240 B2B). La part RGZ par équipe se règle dans Suivi Équipes.
A39: Commission par vente B2B | C39: 12000

Sheet Saisie B2C
A1: Saisie B2C : ventes validées par jour
A2: Chaque soir, saisir le nombre de ventes validées dans la colonne du jour. Les colonnes grises sont des jours non ouvrés par défaut.
A3: Exemple : un agent a 2 ventes validées le lundi 5 octobre → saisir 2 dans la colonne « 5 lun ».
A5: Équipe | B5: Login | C5: Éligible | D5: 1 jeu | E5: 2 ven | F5: 3 sam | G5: 4 dim | H5: 5 lun | I5: 6 mar | J5: 7 mer | K5: 8 jeu | L5: 9 ven | M5: 10 sam | N5: 11 dim | O5: 12 lun | P5: 13 mar | Q5: 14 mer | R5: 15 jeu | S5: 16 ven | T5: 17 sam | U5: 18 dim | V5: 19 lun | W5: 20 mar | X5: 21 mer | Y5: 22 jeu | Z5: 23 ven | AA5: 24 sam | AB5: 25 dim | AC5: 26 lun | AD5: 27 mar | AE5: 28 mer | AF5: 29 jeu | AG5: 30 ven | AH5: 31 sam
A6: YANKEE | B6: pms_rgz_tosee.ftth | C6: Oui
A7: YANKEE | B7: pvt_rgz_mfrancois.ftth | C7: Oui
A8: YANKEE | B8: pvt_rgz_fadji.ftth | C8: Oui
A9: YANKEE | B9: pvt_rgz_dcharmelie.ftth | C9: Oui
A10: YANKEE | B10: pvt_rgz_gkohla.ftth | C10: Oui
A11: YANKEE | B11: pvt_rgz_rclotoe.ftth | C11: Oui
A12: YANKEE | B12: pvt_rgz_aconstant.ftth | C12: Oui
A13: YANKEE | B13: pvt_rgz_cmessinou.ftth | C13: Oui
A14: YANKEE | B14: pvt_rgz_lsenakpon.ftth | C14: Oui
A15: YANKEE | B15: pvt_rgz_tletitia.ftth | C15: Oui
A16: YANKEE | B16: pvt_rgz_dalexis.ftth | C16: Oui
A17: YANKEE | B17: pvt_rgz_eulisse.ftth | C17: Oui
... A48: OMEGA | B48: pvt_rgz_ojeovani.ftth | C48: Oui
A49: TOTAL | D49: =SUM(D6:D48) -> 0 | E49: =SUM(E6:E48) -> 0 | F49: =SUM(F6:F48) -> 0 | G49: =SUM(G6:G48) -> 0 | H49: =SUM(H6:H48) -> 0 | I49: =SUM(I6:I48) -> 0 | J49: =SUM(J6:J48) -> 0 | K49: =SUM(K6:K48) -> 0 | ... AH49: =SUM(AH6:AH48) -> 0

Sheet Saisie B2B
A1: Saisie B2B : ventes validées par jour
A2: Chaque soir, saisir le nombre de ventes validées dans la colonne du jour. Les colonnes grises sont des jours non ouvrés par défaut.
A3: Exemple : un agent a 2 ventes validées le lundi 5 octobre → saisir 2 dans la colonne « 5 lun ».
A5: Équipe | B5: Login | D5: 1 jeu | E5: 2 ven | F5: 3 sam | G5: 4 dim | H5: 5 lun | I5: 6 mar | J5: 7 mer | K5: 8 jeu | L5: 9 ven | M5: 10 sam | N5: 11 dim | O5: 12 lun | P5: 13 mar | Q5: 14 mer | R5: 15 jeu | S5: 16 ven | T5: 17 sam | U5: 18 dim | V5: 19 lun | W5: 20 mar | X5: 21 mer | Y5: 22 jeu | Z5: 23 ven | AA5: 24 sam | AB5: 25 dim | AC5: 26 lun | AD5: 27 mar | AE5: 28 mer | AF5: 29 jeu | AG5: 30 ven | AH5: 31 sam
A6: YANKEE | B6: pms_rgz_tosee.ftth
A7: YANKEE | B7: pvt_rgz_mfrancois.ftth
A8: YANKEE | B8: pvt_rgz_fadji.ftth
A9: YANKEE | B9: pvt_rgz_dcharmelie.ftth
A10: YANKEE | B10: pvt_rgz_gkohla.ftth
A11: YANKEE | B11: pvt_rgz_rclotoe.ftth
A12: YANKEE | B12: pvt_rgz_aconstant.ftth
A13: YANKEE | B13: pvt_rgz_cmessinou.ftth
A14: YANKEE | B14: pvt_rgz_lsenakpon.ftth
A15: YANKEE | B15: pvt_rgz_tletitia.ftth
A16: YANKEE | B16: pvt_rgz_dalexis.ftth
A17: YANKEE | B17: pvt_rgz_eulisse.ftth
... A48: OMEGA | B48: pvt_rgz_ojeovani.ftth
A49: TOTAL | D49: =SUM(D6:D48) -> 0 | E49: =SUM(E6:E48) -> 0 | F49: =SUM(F6:F48) -> 0 | G49: =SUM(G6:G48) -> 0 | H49: =SUM(H6:H48) -> 0 | I49: =SUM(I6:I48) -> 0 | J49: =SUM(J6:J48) -> 0 | K49: =SUM(K6:K48) -> 0 | ... AH49: =SUM(AH6:AH48) -> 0

Sheet Tableau du jour
A1: ="Tableau du jour : "&TEXT(INDEX(Paramètres!$B$5:$AF$5,Paramètres!$B$10),"dd/mm/yyyy") -> Tableau du jour : 01/10/2026
A2: Photo de la journée indiquée dans Paramètres (cellule B10), à partager avec l'équipe.
A3: Champion du jour : | C3: =IF(INDEX('Calcul quotidien'!$D$96:$AH$96,Paramètres!$B$10)="","Personne n'a atteint son objectif",INDEX('Calcul quotidien'!$D$96:$AH$96,Paramètres!$B$10)) -> Personne n'a atteint son objectif | F3: =IF(INDEX(Paramètres!$B$7:$AF$7,Paramètres!$B$10)=0,"Jour non ouvré : pas de prime journalière","")
A5: Équipe | B5: Login | C5: Obj. du jour | D5: Ventes du jour | E5: Objectif du jour atteint | F5: Cumul mois | G5: Obj. du mois | H5: TRO mois | I5: Rythme à date
A6: ='Suivi Agents'!A6 -> YANKEE | B6: ='Suivi Agents'!B6 -> pms_rgz_tosee.ftth | C6: ='Suivi Agents'!G6 -> 2 | D6: =INDEX('Calcul quotidien'!$D6:$AH6,Paramètres!$B$10) -> 0 | E6: =IF('Suivi Agents'!F6=0,"",IF(D6>=C6,"Oui","Non")) -> Non | F6: ='Suivi Agents'!K6 -> 0 | G6: ='Suivi Agents'!F6 -> 44 | H6: ='Suivi Agents'!L6 -> 0 | I6: ='Suivi Agents'!N6 -> 0
A7: ='Suivi Agents'!A7 -> YANKEE | B7: ='Suivi Agents'!B7 -> pvt_rgz_mfrancois.ftth | C7: ='Suivi Agents'!G7 -> 1.5909091 | D7: =INDEX('Calcul quotidien'!$D7:$AH7,Paramètres!$B$10) -> 0 | E7: =IF('Suivi Agents'!F7=0,"",IF(D7>=C7,"Oui","Non")) -> Non | F7: ='Suivi Agents'!K7 -> 0 | G7: ='Suivi Agents'!F7 -> 35 | H7: ='Suivi Agents'!L7 -> 0 | I7: ='Suivi Agents'!N7 -> 0
A8: ='Suivi Agents'!A8 -> YANKEE | B8: ='Suivi Agents'!B8 -> pvt_rgz_fadji.ftth | C8: ='Suivi Agents'!G8 -> 1.5454545 | D8: =INDEX('Calcul quotidien'!$D8:$AH8,Paramètres!$B$10) -> 0 | E8: =IF('Suivi Agents'!F8=0,"",IF(D8>=C8,"Oui","Non")) -> Non | F8: ='Suivi Agents'!K8 -> 0 | G8: ='Suivi Agents'!F8 -> 34 | H8: ='Suivi Agents'!L8 -> 0 | I8: ='Suivi Agents'!N8 -> 0
A9: ='Suivi Agents'!A9 -> YANKEE | B9: ='Suivi Agents'!B9 -> pvt_rgz_dcharmelie.ftth | C9: ='Suivi Agents'!G9 -> 1.2727273 | D9: =INDEX('Calcul quotidien'!$D9:$AH9,Paramètres!$B$10) -> 0 | E9: =IF('Suivi Agents'!F9=0,"",IF(D9>=C9,"Oui","Non")) -> Non | F9: ='Suivi Agents'!K9 -> 0 | G9: ='Suivi Agents'!F9 -> 28 | H9: ='Suivi Agents'!L9 -> 0 | I9: ='Suivi Agents'!N9 -> 0
A10: ='Suivi Agents'!A10 -> YANKEE | B10: ='Suivi Agents'!B10 -> pvt_rgz_gkohla.ftth | C10: ='Suivi Agents'!G10 -> 1.6363636 | D10: =INDEX('Calcul quotidien'!$D10:$AH10,Paramètres!$B$10) -> 0 | E10: =IF('Suivi Agents'!F10=0,"",IF(D10>=C10,"Oui","Non")) -> Non | F10: ='Suivi Agents'!K10 -> 0 | G10: ='Suivi Agents'!F10 -> 36 | H10: ='Suivi Agents'!L10 -> 0 | I10: ='Suivi Agents'!N10 -> 0
A11: ='Suivi Agents'!A11 -> YANKEE | B11: ='Suivi Agents'!B11 -> pvt_rgz_rclotoe.ftth | C11: ='Suivi Agents'!G11 -> 1.3636364 | D11: =INDEX('Calcul quotidien'!$D11:$AH11,Paramètres!$B$10) -> 0 | E11: =IF('Suivi Agents'!F11=0,"",IF(D11>=C11,"Oui","Non")) -> Non | F11: ='Suivi Agents'!K11 -> 0 | G11: ='Suivi Agents'!F11 -> 30 | H11: ='Suivi Agents'!L11 -> 0 | I11: ='Suivi Agents'!N11 -> 0
A12: ='Suivi Agents'!A12 -> YANKEE | B12: ='Suivi Agents'!B12 -> pvt_rgz_aconstant.ftth | C12: ='Suivi Agents'!G12 -> 1.1363636 | D12: =INDEX('Calcul quotidien'!$D12:$AH12,Paramètres!$B$10) -> 0 | E12: =IF('Suivi Agents'!F12=0,"",IF(D12>=C12,"Oui","Non")) -> Non | F12: ='Suivi Agents'!K12 -> 0 | G12: ='Suivi Agents'!F12 -> 25 | H12: ='Suivi Agents'!L12 -> 0 | I12: ='Suivi Agents'!N12 -> 0
A13: ='Suivi Agents'!A13 -> YANKEE | B13: ='Suivi Agents'!B13 -> pvt_rgz_cmessinou.ftth | C13: ='Suivi Agents'!G13 -> 1.0454545 | D13: =INDEX('Calcul quotidien'!$D13:$AH13,Paramètres!$B$10) -> 0 | E13: =IF('Suivi Agents'!F13=0,"",IF(D13>=C13,"Oui","Non")) -> Non | F13: ='Suivi Agents'!K13 -> 0 | G13: ='Suivi Agents'!F13 -> 23 | H13: ='Suivi Agents'!L13 -> 0 | I13: ='Suivi Agents'!N13 -> 0
A14: ='Suivi Agents'!A14 -> YANKEE | B14: ='Suivi Agents'!B14 -> pvt_rgz_lsenakpon.ftth | C14: ='Suivi Agents'!G14 -> 1.8181818 | D14: =INDEX('Calcul quotidien'!$D14:$AH14,Paramètres!$B$10) -> 0 | E14: =IF('Suivi Agents'!F14=0,"",IF(D14>=C14,"Oui","Non")) -> Non | F14: ='Suivi Agents'!K14 -> 0 | G14: ='Suivi Agents'!F14 -> 40 | H14: ='Suivi Agents'!L14 -> 0 | I14: ='Suivi Agents'!N14 -> 0
A15: ='Suivi Agents'!A15 -> YANKEE | B15: ='Suivi Agents'!B15 -> pvt_rgz_tletitia.ftth | C15: ='Suivi Agents'!G15 -> 0.90909091 | D15: =INDEX('Calcul quotidien'!$D15:$AH15,Paramètres!$B$10) -> 0 | E15: =IF('Suivi Agents'!F15=0,"",IF(D15>=C15,"Oui","Non")) -> Non | F15: ='Suivi Agents'!K15 -> 0 | G15: ='Suivi Agents'!F15 -> 20 | H15: ='Suivi Agents'!L15 -> 0 | I15: ='Suivi Agents'!N15 -> 0
A16: ='Suivi Agents'!A16 -> YANKEE | B16: ='Suivi Agents'!B16 -> pvt_rgz_dalexis.ftth | C16: ='Suivi Agents'!G16 -> 0.68181818 | D16: =INDEX('Calcul quotidien'!$D16:$AH16,Paramètres!$B$10) -> 0 | E16: =IF('Suivi Agents'!F16=0,"",IF(D16>=C16,"Oui","Non")) -> Non | F16: ='Suivi Agents'!K16 -> 0 | G16: ='Suivi Agents'!F16 -> 15 | H16: ='Suivi Agents'!L16 -> 0 | I16: ='Suivi Agents'!N16 -> 0
A17: ='Suivi Agents'!A17 -> YANKEE | B17: ='Suivi Agents'!B17 -> pvt_rgz_eulisse.ftth | C17: ='Suivi Agents'!G17 -> 0.45454545 | D17: =INDEX('Calcul quotidien'!$D17:$AH17,Paramètres!$B$10) -> 0 | E17: =IF('Suivi Agents'!F17=0,"",IF(D17>=C17,"Oui","Non")) -> Non | F17: ='Suivi Agents'!K17 -> 0 | G17: ='Suivi Agents'!F17 -> 10 | H17: ='Suivi Agents'!L17 -> 0 | I17: ='Suivi Agents'!N17 -> 0
... A48: ='Suivi Agents'!A48 -> OMEGA | B48: ='Suivi Agents'!B48 -> pvt_rgz_ojeovani.ftth | C48: ='Suivi Agents'!G48 -> 1.3636364 | D48: =INDEX('Calcul quotidien'!$D48:$AH48,Paramètres!$B$10) -> 0 | E48: =IF('Suivi Agents'!F48=0,"",IF(D48>=C48,"Oui","Non")) -> Non | F48: ='Suivi Agents'!K48 -> 0 | G48: ='Suivi Agents'!F48 -> 30 | H48: ='Suivi Agents'!L48 -> 0 | I48: ='Suivi Agents'!N48 -> 0
A51: Équipe | B51: Superviseur | C51: Obj. du jour | D51: Ventes du jour | E51: Objectif du jour atteint | F51: Cumul mois | G51: Obj. du mois | H51: TRO mois | I51: Rythme à date
A52: YANKEE | B52: ='Suivi Équipes'!B6&"" | C52: ='Suivi Équipes'!F6 -> 15.454545 | D52: =INDEX('Calcul quotidien'!$D99:$AH99,Paramètres!$B$10) -> 0 | E52: =IF(D52>=C52,"Oui","Non") -> Non | F52: ='Suivi Équipes'!H6 -> 0 | G52: ='Suivi Équipes'!E6 -> 340 | H52: ='Suivi Équipes'!I6 -> 0 | I52: ='Suivi Équipes'!J6 -> 0
A53: ALPHA | B53: ='Suivi Équipes'!B7&"" | C53: ='Suivi Équipes'!F7 -> 4.5454545 | D53: =INDEX('Calcul quotidien'!$D100:$AH100,Paramètres!$B$10) -> 0 | E53: =IF(D53>=C53,"Oui","Non") -> Non | F53: ='Suivi Équipes'!H7 -> 0 | G53: ='Suivi Équipes'!E7 -> 100 | H53: ='Suivi Équipes'!I7 -> 0 | I53: ='Suivi Équipes'!J7 -> 0
A54: TANGO | B54: ='Suivi Équipes'!B8&"" | C54: ='Suivi Équipes'!F8 -> 9.5454545 | D54: =INDEX('Calcul quotidien'!$D101:$AH101,Paramètres!$B$10) -> 0 | E54: =IF(D54>=C54,"Oui","Non") -> Non | F54: ='Suivi Équipes'!H8 -> 0 | G54: ='Suivi Équipes'!E8 -> 210 | H54: ='Suivi Équipes'!I8 -> 0 | I54: ='Suivi Équipes'!J8 -> 0
A55: ZULU | B55: ='Suivi Équipes'!B9&"" | C55: ='Suivi Équipes'!F9 -> 5.4545455 | D55: =INDEX('Calcul quotidien'!$D102:$AH102,Paramètres!$B$10) -> 0 | E55: =IF(D55>=C55,"Oui","Non") -> Non | F55: ='Suivi Équipes'!H9 -> 0 | G55: ='Suivi Équipes'!E9 -> 120 | H55: ='Suivi Équipes'!I9 -> 0 | I55: ='Suivi Équipes'!J9 -> 0
A56: CHARLIE | B56: ='Suivi Équipes'!B10&"" | C56: ='Suivi Équipes'!F10 -> 3.6363636 | D56: =INDEX('Calcul quotidien'!$D103:$AH103,Paramètres!$B$10) -> 0 | E56: =IF(D56>=C56,"Oui","Non") -> Non | F56: ='Suivi Équipes'!H10 -> 0 | G56: ='Suivi Équipes'!E10 -> 80 | H56: ='Suivi Équipes'!I10 -> 0 | I56: ='Suivi Équipes'!J10 -> 0
A57: MIKE | B57: ='Suivi Équipes'!B11&"" | C57: ='Suivi Équipes'!F11 -> 5.9090909 | D57: =INDEX('Calcul quotidien'!$D104:$AH104,Paramètres!$B$10) -> 0 | E57: =IF(D57>=C57,"Oui","Non") -> Non | F57: ='Suivi Équipes'!H11 -> 0 | G57: ='Suivi Équipes'!E11 -> 130 | H57: ='Suivi Équipes'!I11 -> 0 | I57: ='Suivi Équipes'!J11 -> 0
A58: ANONYMAT | B58: ='Suivi Équipes'!B12&"" | C58: ='Suivi Équipes'!F12 -> 6.3636364 | D58: =INDEX('Calcul quotidien'!$D105:$AH105,Paramètres!$B$10) -> 0 | E58: =IF(D58>=C58,"Oui","Non") -> Non | F58: ='Suivi Équipes'!H12 -> 0 | G58: ='Suivi Équipes'!E12 -> 140 | H58: ='Suivi Équipes'!I12 -> 0 | I58: ='Suivi Équipes'!J12 -> 0
A59: CONCORDE | B59: ='Suivi Équipes'!B13&"" | C59: ='Suivi Équipes'!F13 -> 7.5909091 | D59: =INDEX('Calcul quotidien'!$D106:$AH106,Paramètres!$B$10) -> 0 | E59: =IF(D59>=C59,"Oui","Non") -> Non | F59: ='Suivi Équipes'!H13 -> 0 | G59: ='Suivi Équipes'!E13 -> 167 | H59: ='Suivi Équipes'!I13 -> 0 | I59: ='Suivi Équipes'!J13 -> 0
A60: BRAVO | B60: ='Suivi Équipes'!B14&"" | C60: ='Suivi Équipes'!F14 -> 4.5454545 | D60: =INDEX('Calcul quotidien'!$D107:$AH107,Paramètres!$B$10) -> 0 | E60: =IF(D60>=C60,"Oui","Non") -> Non | F60: ='Suivi Équipes'!H14 -> 0 | G60: ='Suivi Équipes'!E14 -> 100 | H60: ='Suivi Équipes'!I14 -> 0 | I60: ='Suivi Équipes'!J14 -> 0
A61: OMEGA | B61: ='Suivi Équipes'!B15&"" | C61: ='Suivi Équipes'!F15 -> 4.5454545 | D61: =INDEX('Calcul quotidien'!$D108:$AH108,Paramètres!$B$10) -> 0 | E61: =IF(D61>=C61,"Oui","Non") -> Non | F61: ='Suivi Équipes'!H15 -> 0 | G61: ='Suivi Équipes'!E15 -> 100 | H61: ='Suivi Équipes'!I15 -> 0 | I61: ='Suivi Équipes'!J15 -> 0

Sheet Suivi Agents
A1: Suivi des agents (cumul du mois)
A2: TRO = réalisé / objectif du mois. Rythme = réalisé / objectif attendu au dernier jour saisi.
A5: Équipe | B5: Login | C5: Éligible | D5: Obj. B2C | E5: Obj. B2B | F5: Obj. total | G5: Obj. du jour | H5: Réalisé sept. | I5: Réal. B2C | J5: Réal. B2B | K5: Réal. total | L5: TRO mois | M5: Obj. à date | N5: Rythme à date | O5: Reste à faire | P5: Journées réussies | Q5: Fois champion du jour | R5: Palier | S5: Prime palier | T5: Primes journées | U5: Primes champion | V5: Bonus B2B | W5: Total primes | X5: Rang | Y5: score
A6: ='Saisie B2C'!A6 -> YANKEE | B6: ='Saisie B2C'!B6 -> pms_rgz_tosee.ftth | C6: ='Saisie B2C'!C6 -> Oui | D6: 30 | E6: 14 | F6: =D6+E6 -> 44 | G6: =F6/Paramètres!$B$9 -> 2 | H6: 54 | I6: =SUM('Saisie B2C'!D6:AH6) -> 0 | J6: =SUM('Saisie B2B'!D6:AH6) -> 0 | K6: =I6+J6 -> 0 | L6: =IF(F6>0,K6/F6,"") -> 0 | M6: =F6*Paramètres!$B$11/Paramètres!$B$9 -> 2 | N6: =IF(M6>0,K6/M6,"") -> 0 | O6: =IF(F6>0,MAX(0,F6-K6),"") -> 44 | P6: =IF(F6>0,SUMPRODUCT(('Saisie B2C'!D6:AH6+'Saisie B2B'!D6:AH6>=G6)*(Paramètres!$B$7:$AF$7=1)*(Paramètres!$B$4:$AF$4<=Paramètres!$B$10)),0) -> 0 | Q6: =COUNTIF('Calcul quotidien'!$D$96:$AH$96,B6) -> 0 | R6: =IF(OR(F6=0,C6<>"Oui"),"Non éligible",INDEX(Paramètres!$A$15:$A$18,MATCH(L6,Paramètres!$B$15:$B$18,1))) -> Aucun | S6: =IF(R6="Non éligible",0,INDEX(Paramètres!$C$15:$C$18,MATCH(L6,Paramètres!$B$15:$B$18,1))) -> 0 | T6: =IF(R6="Non éligible",0,P6*Paramètres!$C$20) -> 0 | U6: =IF(R6="Non éligible",0,Q6*Paramètres!$C$21) -> 0 | V6: =IF(AND(R6<>"Non éligible",E6>0,J6>=E6),Paramètres!$C$22,0) -> 0 | W6: =S6+T6+U6+V6 -> 0 | X6: =IF(Y6<0,"",RANK(Y6,$Y$6:$Y$48)) -> 1 | Y6: =IF(R6="Non éligible",-1,L6+K6/100000+(1000-ROW())/100000000) -> 9.94e-06
A7: ='Saisie B2C'!A7 -> YANKEE | B7: ='Saisie B2C'!B7 -> pvt_rgz_mfrancois.ftth | C7: ='Saisie B2C'!C7 -> Oui | D7: 30 | E7: 5 | F7: =D7+E7 -> 35 | G7: =F7/Paramètres!$B$9 -> 1.5909091 | H7: 52 | I7: =SUM('Saisie B2C'!D7:AH7) -> 0 | J7: =SUM('Saisie B2B'!D7:AH7) -> 0 | K7: =I7+J7 -> 0 | L7: =IF(F7>0,K7/F7,"") -> 0 | M7: =F7*Paramètres!$B$11/Paramètres!$B$9 -> 1.5909091 | N7: =IF(M7>0,K7/M7,"") -> 0 | O7: =IF(F7>0,MAX(0,F7-K7),"") -> 35 | P7: =IF(F7>0,SUMPRODUCT(('Saisie B2C'!D7:AH7+'Saisie B2B'!D7:AH7>=G7)*(Paramètres!$B$7:$AF$7=1)*(Paramètres!$B$4:$AF$4<=Paramètres!$B$10)),0) -> 0 | Q7: =COUNTIF('Calcul quotidien'!$D$96:$AH$96,B7) -> 0 | R7: =IF(OR(F7=0,C7<>"Oui"),"Non éligible",INDEX(Paramètres!$A$15:$A$18,MATCH(L7,Paramètres!$B$15:$B$18,1))) -> Aucun | S7: =IF(R7="Non éligible",0,INDEX(Paramètres!$C$15:$C$18,MATCH(L7,Paramètres!$B$15:$B$18,1))) -> 0 | T7: =IF(R7="Non éligible",0,P7*Paramètres!$C$20) -> 0 | U7: =IF(R7="Non éligible",0,Q7*Paramètres!$C$21) -> 0 | V7: =IF(AND(R7<>"Non éligible",E7>0,J7>=E7),Paramètres!$C$22,0) -> 0 | W7: =S7+T7+U7+V7 -> 0 | X7: =IF(Y7<0,"",RANK(Y7,$Y$6:$Y$48)) -> 2 | Y7: =IF(R7="Non éligible",-1,L7+K7/100000+(1000-ROW())/100000000) -> 9.93e-06
A8: ='Saisie B2C'!A8 -> YANKEE | B8: ='Saisie B2C'!B8 -> pvt_rgz_fadji.ftth | C8: ='Saisie B2C'!C8 -> Oui | D8: 30 | E8: 4 | F8: =D8+E8 -> 34 | G8: =F8/Paramètres!$B$9 -> 1.5454545 | H8: 52 | I8: =SUM('Saisie B2C'!D8:AH8) -> 0 | J8: =SUM('Saisie B2B'!D8:AH8) -> 0 | K8: =I8+J8 -> 0 | L8: =IF(F8>0,K8/F8,"") -> 0 | M8: =F8*Paramètres!$B$11/Paramètres!$B$9 -> 1.5454545 | N8: =IF(M8>0,K8/M8,"") -> 0 | O8: =IF(F8>0,MAX(0,F8-K8),"") -> 34 | P8: =IF(F8>0,SUMPRODUCT(('Saisie B2C'!D8:AH8+'Saisie B2B'!D8:AH8>=G8)*(Paramètres!$B$7:$AF$7=1)*(Paramètres!$B$4:$AF$4<=Paramètres!$B$10)),0) -> 0 | Q8: =COUNTIF('Calcul quotidien'!$D$96:$AH$96,B8) -> 0 | R8: =IF(OR(F8=0,C8<>"Oui"),"Non éligible",INDEX(Paramètres!$A$15:$A$18,MATCH(L8,Paramètres!$B$15:$B$18,1))) -> Aucun | S8: =IF(R8="Non éligible",0,INDEX(Paramètres!$C$15:$C$18,MATCH(L8,Paramètres!$B$15:$B$18,1))) -> 0 | T8: =IF(R8="Non éligible",0,P8*Paramètres!$C$20) -> 0 | U8: =IF(R8="Non éligible",0,Q8*Paramètres!$C$21) -> 0 | V8: =IF(AND(R8<>"Non éligible",E8>0,J8>=E8),Paramètres!$C$22,0) -> 0 | W8: =S8+T8+U8+V8 -> 0 | X8: =IF(Y8<0,"",RANK(Y8,$Y$6:$Y$48)) -> 3 | Y8: =IF(R8="Non éligible",-1,L8+K8/100000+(1000-ROW())/100000000) -> 9.92e-06
A9: ='Saisie B2C'!A9 -> YANKEE | B9: ='Saisie B2C'!B9 -> pvt_rgz_dcharmelie.ftth | C9: ='Saisie B2C'!C9 -> Oui | D9: 25 | E9: 3 | F9: =D9+E9 -> 28 | G9: =F9/Paramètres!$B$9 -> 1.2727273 | H9: 40 | I9: =SUM('Saisie B2C'!D9:AH9) -> 0 | J9: =SUM('Saisie B2B'!D9:AH9) -> 0 | K9: =I9+J9 -> 0 | L9: =IF(F9>0,K9/F9,"") -> 0 | M9: =F9*Paramètres!$B$11/Paramètres!$B$9 -> 1.2727273 | N9: =IF(M9>0,K9/M9,"") -> 0 | O9: =IF(F9>0,MAX(0,F9-K9),"") -> 28 | P9: =IF(F9>0,SUMPRODUCT(('Saisie B2C'!D9:AH9+'Saisie B2B'!D9:AH9>=G9)*(Paramètres!$B$7:$AF$7=1)*(Paramètres!$B$4:$AF$4<=Paramètres!$B$10)),0) -> 0 | Q9: =COUNTIF('Calcul quotidien'!$D$96:$AH$96,B9) -> 0 | R9: =IF(OR(F9=0,C9<>"Oui"),"Non éligible",INDEX(Paramètres!$A$15:$A$18,MATCH(L9,Paramètres!$B$15:$B$18,1))) -> Aucun | S9: =IF(R9="Non éligible",0,INDEX(Paramètres!$C$15:$C$18,MATCH(L9,Paramètres!$B$15:$B$18,1))) -> 0 | T9: =IF(R9="Non éligible",0,P9*Paramètres!$C$20) -> 0 | U9: =IF(R9="Non éligible",0,Q9*Paramètres!$C$21) -> 0 | V9: =IF(AND(R9<>"Non éligible",E9>0,J9>=E9),Paramètres!$C$22,0) -> 0 | W9: =S9+T9+U9+V9 -> 0 | X9: =IF(Y9<0,"",RANK(Y9,$Y$6:$Y$48)) -> 4 | Y9: =IF(R9="Non éligible",-1,L9+K9/100000+(1000-ROW())/100000000) -> 9.91e-06
A10: ='Saisie B2C'!A10 -> YANKEE | B10: ='Saisie B2C'!B10 -> pvt_rgz_gkohla.ftth | C10: ='Saisie B2C'!C10 -> Oui | D10: 30 | E10: 6 | F10: =D10+E10 -> 36 | G10: =F10/Paramètres!$B$9 -> 1.6363636 | H10: 37 | I10: =SUM('Saisie B2C'!D10:AH10) -> 0 | J10: =SUM('Saisie B2B'!D10:AH10) -> 0 | K10: =I10+J10 -> 0 | L10: =IF(F10>0,K10/F10,"") -> 0 | M10: =F10*Paramètres!$B$11/Paramètres!$B$9 -> 1.6363636 | N10: =IF(M10>0,K10/M10,"") -> 0 | O10: =IF(F10>0,MAX(0,F10-K10),"") -> 36 | P10: =IF(F10>0,SUMPRODUCT(('Saisie B2C'!D10:AH10+'Saisie B2B'!D10:AH10>=G10)*(Paramètres!$B$7:$AF$7=1)*(Paramètres!$B$4:$AF$4<=Paramètres!$B$10)),0) -> 0 | Q10: =COUNTIF('Calcul quotidien'!$D$96:$AH$96,B10) -> 0 | R10: =IF(OR(F10=0,C10<>"Oui"),"Non éligible",INDEX(Paramètres!$A$15:$A$18,MATCH(L10,Paramètres!$B$15:$B$18,1))) -> Aucun | S10: =IF(R10="Non éligible",0,INDEX(Paramètres!$C$15:$C$18,MATCH(L10,Paramètres!$B$15:$B$18,1))) -> 0 | T10: =IF(R10="Non éligible",0,P10*Paramètres!$C$20) -> 0 | U10: =IF(R10="Non éligible",0,Q10*Paramètres!$C$21) -> 0 | V10: =IF(AND(R10<>"Non éligible",E10>0,J10>=E10),Paramètres!$C$22,0) -> 0 | W10: =S10+T10+U10+V10 -> 0 | X10: =IF(Y10<0,"",RANK(Y10,$Y$6:$Y$48)) -> 5 | Y10: =IF(R10="Non éligible",-1,L10+K10/100000+(1000-ROW())/100000000) -> 9.9e-06
A11: ='Saisie B2C'!A11 -> YANKEE | B11: ='Saisie B2C'!B11 -> pvt_rgz_rclotoe.ftth | C11: ='Saisie B2C'!C11 -> Oui | D11: 25 | E11: 5 | F11: =D11+E11 -> 30 | G11: =F11/Paramètres!$B$9 -> 1.3636364 | H11: 36 | I11: =SUM('Saisie B2C'!D11:AH11) -> 0 | J11: =SUM('Saisie B2B'!D11:AH11) -> 0 | K11: =I11+J11 -> 0 | L11: =IF(F11>0,K11/F11,"") -> 0 | M11: =F11*Paramètres!$B$11/Paramètres!$B$9 -> 1.3636364 | N11: =IF(M11>0,K11/M11,"") -> 0 | O11: =IF(F11>0,MAX(0,F11-K11),"") -> 30 | P11: =IF(F11>0,SUMPRODUCT(('Saisie B2C'!D11:AH11+'Saisie B2B'!D11:AH11>=G11)*(Paramètres!$B$7:$AF$7=1)*(Paramètres!$B$4:$AF$4<=Paramètres!$B$10)),0) -> 0 | Q11: =COUNTIF('Calcul quotidien'!$D$96:$AH$96,B11) -> 0 | R11: =IF(OR(F11=0,C11<>"Oui"),"Non éligible",INDEX(Paramètres!$A$15:$A$18,MATCH(L11,Paramètres!$B$15:$B$18,1))) -> Aucun | S11: =IF(R11="Non éligible",0,INDEX(Paramètres!$C$15:$C$18,MATCH(L11,Paramètres!$B$15:$B$18,1))) -> 0 | T11: =IF(R11="Non éligible",0,P11*Paramètres!$C$20) -> 0 | U11: =IF(R11="Non éligible",0,Q11*Paramètres!$C$21) -> 0 | V11: =IF(AND(R11<>"Non éligible",E11>0,J11>=E11),Paramètres!$C$22,0) -> 0 | W11: =S11+T11+U11+V11 -> 0 | X11: =IF(Y11<0,"",RANK(Y11,$Y$6:$Y$48)) -> 6 | Y11: =IF(R11="Non éligible",-1,L11+K11/100000+(1000-ROW())/100000000) -> 9.89e-06
A12: ='Saisie B2C'!A12 -> YANKEE | B12: ='Saisie B2C'!B12 -> pvt_rgz_aconstant.ftth | C12: ='Saisie B2C'!C12 -> Oui | D12: 20 | E12: 5 | F12: =D12+E12 -> 25 | G12: =F12/Paramètres!$B$9 -> 1.1363636 | H12: 35 | I12: =SUM('Saisie B2C'!D12:AH12) -> 0 | J12: =SUM('Saisie B2B'!D12:AH12) -> 0 | K12: =I12+J12 -> 0 | L12: =IF(F12>0,K12/F12,"") -> 0 | M12: =F12*Paramètres!$B$11/Paramètres!$B$9 -> 1.1363636 | N12: =IF(M12>0,K12/M12,"") -> 0 | O12: =IF(F12>0,MAX(0,F12-K12),"") -> 25 | P12: =IF(F12>0,SUMPRODUCT(('Saisie B2C'!D12:AH12+'Saisie B2B'!D12:AH12>=G12)*(Paramètres!$B$7:$AF$7=1)*(Paramètres!$B$4:$AF$4<=Paramètres!$B$10)),0) -> 0 | Q12: =COUNTIF('Calcul quotidien'!$D$96:$AH$96,B12) -> 0 | R12: =IF(OR(F12=0,C12<>"Oui"),"Non éligible",INDEX(Paramètres!$A$15:$A$18,MATCH(L12,Paramètres!$B$15:$B$18,1))) -> Aucun | S12: =IF(R12="Non éligible",0,INDEX(Paramètres!$C$15:$C$18,MATCH(L12,Paramètres!$B$15:$B$18,1))) -> 0 | T12: =IF(R12="Non éligible",0,P12*Paramètres!$C$20) -> 0 | U12: =IF(R12="Non éligible",0,Q12*Paramètres!$C$21) -> 0 | V12: =IF(AND(R12<>"Non éligible",E12>0,J12>=E12),Paramètres!$C$22,0) -> 0 | W12: =S12+T12+U12+V12 -> 0 | X12: =IF(Y12<0,"",RANK(Y12,$Y$6:$Y$48)) -> 7 | Y12: =IF(R12="Non éligible",-1,L12+K12/100000+(1000-ROW())/100000000) -> 9.88e-06
A13: ='Saisie B2C'!A13 -> YANKEE | B13: ='Saisie B2C'!B13 -> pvt_rgz_cmessinou.ftth | C13: ='Saisie B2C'!C13 -> Oui | D13: 20 | E13: 3 | F13: =D13+E13 -> 23 | G13: =F13/Paramètres!$B$9 -> 1.0454545 | H13: 35 | I13: =SUM('Saisie B2C'!D13:AH13) -> 0 | J13: =SUM('Saisie B2B'!D13:AH13) -> 0 | K13: =I13+J13 -> 0 | L13: =IF(F13>0,K13/F13,"") -> 0 | M13: =F13*Paramètres!$B$11/Paramètres!$B$9 -> 1.0454545 | N13: =IF(M13>0,K13/M13,"") -> 0 | O13: =IF(F13>0,MAX(0,F13-K13),"") -> 23 | P13: =IF(F13>0,SUMPRODUCT(('Saisie B2C'!D13:AH13+'Saisie B2B'!D13:AH13>=G13)*(Paramètres!$B$7:$AF$7=1)*(Paramètres!$B$4:$AF$4<=Paramètres!$B$10)),0) -> 0 | Q13: =COUNTIF('Calcul quotidien'!$D$96:$AH$96,B13) -> 0 | R13: =IF(OR(F13=0,C13<>"Oui"),"Non éligible",INDEX(Paramètres!$A$15:$A$18,MATCH(L13,Paramètres!$B$15:$B$18,1))) -> Aucun | S13: =IF(R13="Non éligible",0,INDEX(Paramètres!$C$15:$C$18,MATCH(L13,Paramètres!$B$15:$B$18,1))) -> 0 | T13: =IF(R13="Non éligible",0,P13*Paramètres!$C$20) -> 0 | U13: =IF(R13="Non éligible",0,Q13*Paramètres!$C$21) -> 0 | V13: =IF(AND(R13<>"Non éligible",E13>0,J13>=E13),Paramètres!$C$22,0) -> 0 | W13: =S13+T13+U13+V13 -> 0 | X13: =IF(Y13<0,"",RANK(Y13,$Y$6:$Y$48)) -> 8 | Y13: =IF(R13="Non éligible",-1,L13+K13/100000+(1000-ROW())/100000000) -> 9.87e-06
A14: ='Saisie B2C'!A14 -> YANKEE | B14: ='Saisie B2C'!B14 -> pvt_rgz_lsenakpon.ftth | C14: ='Saisie B2C'!C14 -> Oui | D14: 35 | E14: 5 | F14: =D14+E14 -> 40 | G14: =F14/Paramètres!$B$9 -> 1.8181818 | H14: 34 | I14: =SUM('Saisie B2C'!D14:AH14) -> 0 | J14: =SUM('Saisie B2B'!D14:AH14) -> 0 | K14: =I14+J14 -> 0 | L14: =IF(F14>0,K14/F14,"") -> 0 | M14: =F14*Paramètres!$B$11/Paramètres!$B$9 -> 1.8181818 | N14: =IF(M14>0,K14/M14,"") -> 0 | O14: =IF(F14>0,MAX(0,F14-K14),"") -> 40 | P14: =IF(F14>0,SUMPRODUCT(('Saisie B2C'!D14:AH14+'Saisie B2B'!D14:AH14>=G14)*(Paramètres!$B$7:$AF$7=1)*(Paramètres!$B$4:$AF$4<=Paramètres!$B$10)),0) -> 0 | Q14: =COUNTIF('Calcul quotidien'!$D$96:$AH$96,B14) -> 0 | R14: =IF(OR(F14=0,C14<>"Oui"),"Non éligible",INDEX(Paramètres!$A$15:$A$18,MATCH(L14,Paramètres!$B$15:$B$18,1))) -> Aucun | S14: =IF(R14="Non éligible",0,INDEX(Paramètres!$C$15:$C$18,MATCH(L14,Paramètres!$B$15:$B$18,1))) -> 0 | T14: =IF(R14="Non éligible",0,P14*Paramètres!$C$20) -> 0 | U14: =IF(R14="Non éligible",0,Q14*Paramètres!$C$21) -> 0 | V14: =IF(AND(R14<>"Non éligible",E14>0,J14>=E14),Paramètres!$C$22,0) -> 0 | W14: =S14+T14+U14+V14 -> 0 | X14: =IF(Y14<0,"",RANK(Y14,$Y$6:$Y$48)) -> 9 | Y14: =IF(R14="Non éligible",-1,L14+K14/100000+(1000-ROW())/100000000) -> 9.86e-06
A15: ='Saisie B2C'!A15 -> YANKEE | B15: ='Saisie B2C'!B15 -> pvt_rgz_tletitia.ftth | C15: ='Saisie B2C'!C15 -> Oui | D15: 20 | E15: 0 | F15: =D15+E15 -> 20 | G15: =F15/Paramètres!$B$9 -> 0.90909091 | H15: 30 | I15: =SUM('Saisie B2C'!D15:AH15) -> 0 | J15: =SUM('Saisie B2B'!D15:AH15) -> 0 | K15: =I15+J15 -> 0 | L15: =IF(F15>0,K15/F15,"") -> 0 | M15: =F15*Paramètres!$B$11/Paramètres!$B$9 -> 0.90909091 | N15: =IF(M15>0,K15/M15,"") -> 0 | O15: =IF(F15>0,MAX(0,F15-K15),"") -> 20 | P15: =IF(F15>0,SUMPRODUCT(('Saisie B2C'!D15:AH15+'Saisie B2B'!D15:AH15>=G15)*(Paramètres!$B$7:$AF$7=1)*(Paramètres!$B$4:$AF$4<=Paramètres!$B$10)),0) -> 0 | Q15: =COUNTIF('Calcul quotidien'!$D$96:$AH$96,B15) -> 0 | R15: =IF(OR(F15=0,C15<>"Oui"),"Non éligible",INDEX(Paramètres!$A$15:$A$18,MATCH(L15,Paramètres!$B$15:$B$18,1))) -> Aucun | S15: =IF(R15="Non éligible",0,INDEX(Paramètres!$C$15:$C$18,MATCH(L15,Paramètres!$B$15:$B$18,1))) -> 0 | T15: =IF(R15="Non éligible",0,P15*Paramètres!$C$20) -> 0 | U15: =IF(R15="Non éligible",0,Q15*Paramètres!$C$21) -> 0 | V15: =IF(AND(R15<>"Non éligible",E15>0,J15>=E15),Paramètres!$C$22,0) -> 0 | W15: =S15+T15+U15+V15 -> 0 | X15: =IF(Y15<0,"",RANK(Y15,$Y$6:$Y$48)) -> 10 | Y15: =IF(R15="Non éligible",-1,L15+K15/100000+(1000-ROW())/100000000) -> 9.85e-06
A16: ='Saisie B2C'!A16 -> YANKEE | B16: ='Saisie B2C'!B16 -> pvt_rgz_dalexis.ftth | C16: ='Saisie B2C'!C16 -> Oui | D16: 15 | E16: 0 | F16: =D16+E16 -> 15 | G16: =F16/Paramètres!$B$9 -> 0.68181818 | H16: 6 | I16: =SUM('Saisie B2C'!D16:AH16) -> 0 | J16: =SUM('Saisie B2B'!D16:AH16) -> 0 | K16: =I16+J16 -> 0 | L16: =IF(F16>0,K16/F16,"") -> 0 | M16: =F16*Paramètres!$B$11/Paramètres!$B$9 -> 0.68181818 | N16: =IF(M16>0,K16/M16,"") -> 0 | O16: =IF(F16>0,MAX(0,F16-K16),"") -> 15 | P16: =IF(F16>0,SUMPRODUCT(('Saisie B2C'!D16:AH16+'Saisie B2B'!D16:AH16>=G16)*(Paramètres!$B$7:$AF$7=1)*(Paramètres!$B$4:$AF$4<=Paramètres!$B$10)),0) -> 0 | Q16: =COUNTIF('Calcul quotidien'!$D$96:$AH$96,B16) -> 0 | R16: =IF(OR(F16=0,C16<>"Oui"),"Non éligible",INDEX(Paramètres!$A$15:$A$18,MATCH(L16,Paramètres!$B$15:$B$18,1))) -> Aucun | S16: =IF(R16="Non éligible",0,INDEX(Paramètres!$C$15:$C$18,MATCH(L16,Paramètres!$B$15:$B$18,1))) -> 0 | T16: =IF(R16="Non éligible",0,P16*Paramètres!$C$20) -> 0 | U16: =IF(R16="Non éligible",0,Q16*Paramètres!$C$21) -> 0 | V16: =IF(AND(R16<>"Non éligible",E16>0,J16>=E16),Paramètres!$C$22,0) -> 0 | W16: =S16+T16+U16+V16 -> 0 | X16: =IF(Y16<0,"",RANK(Y16,$Y$6:$Y$48)) -> 11 | Y16: =IF(R16="Non éligible",-1,L16+K16/100000+(1000-ROW())/100000000) -> 9.84e-06
A17: ='Saisie B2C'!A17 -> YANKEE | B17: ='Saisie B2C'!B17 -> pvt_rgz_eulisse.ftth | C17: ='Saisie B2C'!C17 -> Oui | D17: 10 | E17: 0 | F17: =D17+E17 -> 10 | G17: =F17/Paramètres!$B$9 -> 0.45454545 | H17: 1 | I17: =SUM('Saisie B2C'!D17:AH17) -> 0 | J17: =SUM('Saisie B2B'!D17:AH17) -> 0 | K17: =I17+J17 -> 0 | L17: =IF(F17>0,K17/F17,"") -> 0 | M17: =F17*Paramètres!$B$11/Paramètres!$B$9 -> 0.45454545 | N17: =IF(M17>0,K17/M17,"") -> 0 | O17: =IF(F17>0,MAX(0,F17-K17),"") -> 10 | P17: =IF(F17>0,SUMPRODUCT(('Saisie B2C'!D17:AH17+'Saisie B2B'!D17:AH17>=G17)*(Paramètres!$B$7:$AF$7=1)*(Paramètres!$B$4:$AF$4<=Paramètres!$B$10)),0) -> 0 | Q17: =COUNTIF('Calcul quotidien'!$D$96:$AH$96,B17) -> 0 | R17: =IF(OR(F17=0,C17<>"Oui"),"Non éligible",INDEX(Paramètres!$A$15:$A$18,MATCH(L17,Paramètres!$B$15:$B$18,1))) -> Aucun | S17: =IF(R17="Non éligible",0,INDEX(Paramètres!$C$15:$C$18,MATCH(L17,Paramètres!$B$15:$B$18,1))) -> 0 | T17: =IF(R17="Non éligible",0,P17*Paramètres!$C$20) -> 0 | U17: =IF(R17="Non éligible",0,Q17*Paramètres!$C$21) -> 0 | V17: =IF(AND(R17<>"Non éligible",E17>0,J17>=E17),Paramètres!$C$22,0) -> 0 | W17: =S17+T17+U17+V17 -> 0 | X17: =IF(Y17<0,"",RANK(Y17,$Y$6:$Y$48)) -> 12 | Y17: =IF(R17="Non éligible",-1,L17+K17/100000+(1000-ROW())/100000000) -> 9.83e-06
... A48: ='Saisie B2C'!A48 -> OMEGA | B48: ='Saisie B2C'!B48 -> pvt_rgz_ojeovani.ftth | C48: ='Saisie B2C'!C48 -> Oui | D48: 20 | E48: 10 | F48: =D48+E48 -> 30 | G48: =F48/Paramètres!$B$9 -> 1.3636364 | H48: 0 | I48: =SUM('Saisie B2C'!D48:AH48) -> 0 | J48: =SUM('Saisie B2B'!D48:AH48) -> 0 | K48: =I48+J48 -> 0 | L48: =IF(F48>0,K48/F48,"") -> 0 | M48: =F48*Paramètres!$B$11/Paramètres!$B$9 -> 1.3636364 | N48: =IF(M48>0,K48/M48,"") -> 0 | O48: =IF(F48>0,MAX(0,F48-K48),"") -> 30 | P48: =IF(F48>0,SUMPRODUCT(('Saisie B2C'!D48:AH48+'Saisie B2B'!D48:AH48>=G48)*(Paramètres!$B$7:$AF$7=1)*(Paramètres!$B$4:$AF$4<=Paramètres!$B$10)),0) -> 0 | Q48: =COUNTIF('Calcul quotidien'!$D$96:$AH$96,B48) -> 0 | R48: =IF(OR(F48=0,C48<>"Oui"),"Non éligible",INDEX(Paramètres!$A$15:$A$18,MATCH(L48,Paramètres!$B$15:$B$18,1))) -> Aucun | S48: =IF(R48="Non éligible",0,INDEX(Paramètres!$C$15:$C$18,MATCH(L48,Paramètres!$B$15:$B$18,1))) -> 0 | T48: =IF(R48="Non éligible",0,P48*Paramètres!$C$20) -> 0 | U48: =IF(R48="Non éligible",0,Q48*Paramètres!$C$21) -> 0 | V48: =IF(AND(R48<>"Non éligible",E48>0,J48>=E48),Paramètres!$C$22,0) -> 0 | W48: =S48+T48+U48+V48 -> 0 | X48: =IF(Y48<0,"",RANK(Y48,$Y$6:$Y$48)) -> 41 | Y48: =IF(R48="Non éligible",-1,L48+K48/100000+(1000-ROW())/100000000) -> 9.52e-06
A49: TOTAL | D49: =SUM(D6:D48) -> 1247 | E49: =SUM(E6:E48) -> 240 | F49: =SUM(F6:F48) -> 1487 | G49: =SUM(G6:G48) -> 67.590909 | H49: =SUM(H6:H48) -> 1167 | I49: =SUM(I6:I48) -> 0 | J49: =SUM(J6:J48) -> 0 | K49: =SUM(K6:K48) -> 0 | L49: =IF(F49>0,K49/F49,"") -> 0 | M49: =SUM(M6:M48) -> 67.590909 | N49: =IF(M49>0,K49/M49,"") -> 0 | O49: =SUM(O6:O48) -> 1487 | P49: =SUM(P6:P48) -> 0 | Q49: =SUM(Q6:Q48) -> 0 | S49: =SUM(S6:S48) -> 0 | T49: =SUM(T6:T48) -> 0 | U49: =SUM(U6:U48) -> 0 | V49: =SUM(V6:V48) -> 0 | W49: =SUM(W6:W48) -> 0

Sheet Suivi Équipes
A1: Suivi des équipes et des superviseurs (cumul du mois)
A2: La prime de fin de mois est bloquée si le taux d'activation de l'équipe est sous le minimum fixé dans Paramètres.
A5: Équipe | B5: Superviseur | C5: Obj. B2C | D5: Obj. B2B | E5: Obj. total | F5: Obj. du jour | G5: Réalisé sept. | H5: Réal. total | I5: TRO équipe | J5: Rythme à date | K5: Journées équipe réussies | L5: Primes journées | M5: Agents avec objectif | N5: Agents actifs (≥ seuil) | O5: Taux d'activation | P5: Palier | Q5: Prime fin de mois | R5: Rang | S5: Trophée | T5: Total superviseur | U5: Part RGZ | V5: Marge RGZ générée | W5: score
A6: YANKEE | C6: =SUMIF('Suivi Agents'!$A$6:$A$48,$A6,'Suivi Agents'!$D$6:$D$48) -> 290 | D6: =SUMIF('Suivi Agents'!$A$6:$A$48,$A6,'Suivi Agents'!$E$6:$E$48) -> 50 | E6: =SUMIF('Suivi Agents'!$A$6:$A$48,$A6,'Suivi Agents'!$F$6:$F$48) -> 340 | F6: =E6/Paramètres!$B$9 -> 15.454545 | G6: =SUMIF('Suivi Agents'!$A$6:$A$48,$A6,'Suivi Agents'!$H$6:$H$48) -> 413 | H6: =SUMIF('Suivi Agents'!$A$6:$A$48,$A6,'Suivi Agents'!$K$6:$K$48) -> 0 | I6: =IF(E6>0,H6/E6,"") -> 0 | J6: =IF(E6>0,H6/(E6*Paramètres!$B$11/Paramètres!$B$9),"") -> 0 | K6: =SUM('Calcul quotidien'!D111:AH111) -> 0 | L6: =K6*Paramètres!$C$33 -> 0 | M6: =COUNTIFS('Suivi Agents'!$A$6:$A$48,$A6,'Suivi Agents'!$F$6:$F$48,">0") -> 12 | N6: =COUNTIFS('Suivi Agents'!$A$6:$A$48,$A6,'Suivi Agents'!$L$6:$L$48,">="&Paramètres!$C$31) -> 0 | O6: =IF(M6>0,N6/M6,0) -> 0 | P6: =IF(O6<Paramètres!$C$32,"Bloqué (activation)",INDEX(Paramètres!$A$26:$A$29,MATCH(I6,Paramètres!$B$26:$B$29,1))) -> Bloqué (activation) | Q6: =IF(O6<Paramètres!$C$32,0,INDEX(Paramètres!$C$26:$C$29,MATCH(I6,Paramètres!$B$26:$B$29,1))) -> 0 | R6: =RANK(W6,$W$6:$W$15) -> 1 | S6: =IF(AND(R6=1,I6>=Paramètres!$C$35),Paramètres!$C$34,0) -> 0 | T6: =L6+Q6 -> 0 | U6: 0.2 | V6: =(SUMIF('Suivi Agents'!$A$6:$A$48,$A6,'Suivi Agents'!$I$6:$I$48)*Paramètres!$C$38+SUMIF('Suivi Agents'!$A$6:$A$48,$A6,'Suivi Agents'!$J$6:$J$48)*Paramètres!$C$39)*U6 -> 0 | W6: =IF(E6>0,I6+H6/100000+(1000-ROW())/100000000,-1) -> 9.94e-06
A7: ALPHA | C7: =SUMIF('Suivi Agents'!$A$6:$A$48,$A7,'Suivi Agents'!$D$6:$D$48) -> 70 | D7: =SUMIF('Suivi Agents'!$A$6:$A$48,$A7,'Suivi Agents'!$E$6:$E$48) -> 30 | E7: =SUMIF('Suivi Agents'!$A$6:$A$48,$A7,'Suivi Agents'!$F$6:$F$48) -> 100 | F7: =E7/Paramètres!$B$9 -> 4.5454545 | G7: =SUMIF('Suivi Agents'!$A$6:$A$48,$A7,'Suivi Agents'!$H$6:$H$48) -> 77 | H7: =SUMIF('Suivi Agents'!$A$6:$A$48,$A7,'Suivi Agents'!$K$6:$K$48) -> 0 | I7: =IF(E7>0,H7/E7,"") -> 0 | J7: =IF(E7>0,H7/(E7*Paramètres!$B$11/Paramètres!$B$9),"") -> 0 | K7: =SUM('Calcul quotidien'!D112:AH112) -> 0 | L7: =K7*Paramètres!$C$33 -> 0 | M7: =COUNTIFS('Suivi Agents'!$A$6:$A$48,$A7,'Suivi Agents'!$F$6:$F$48,">0") -> 3 | N7: =COUNTIFS('Suivi Agents'!$A$6:$A$48,$A7,'Suivi Agents'!$L$6:$L$48,">="&Paramètres!$C$31) -> 0 | O7: =IF(M7>0,N7/M7,0) -> 0 | P7: =IF(O7<Paramètres!$C$32,"Bloqué (activation)",INDEX(Paramètres!$A$26:$A$29,MATCH(I7,Paramètres!$B$26:$B$29,1))) -> Bloqué (activation) | Q7: =IF(O7<Paramètres!$C$32,0,INDEX(Paramètres!$C$26:$C$29,MATCH(I7,Paramètres!$B$26:$B$29,1))) -> 0 | R7: =RANK(W7,$W$6:$W$15) -> 2 | S7: =IF(AND(R7=1,I7>=Paramètres!$C$35),Paramètres!$C$34,0) -> 0 | T7: =L7+Q7 -> 0 | U7: 0.2 | V7: =(SUMIF('Suivi Agents'!$A$6:$A$48,$A7,'Suivi Agents'!$I$6:$I$48)*Paramètres!$C$38+SUMIF('Suivi Agents'!$A$6:$A$48,$A7,'Suivi Agents'!$J$6:$J$48)*Paramètres!$C$39)*U7 -> 0 | W7: =IF(E7>0,I7+H7/100000+(1000-ROW())/100000000,-1) -> 9.93e-06
A8: TANGO | C8: =SUMIF('Suivi Agents'!$A$6:$A$48,$A8,'Suivi Agents'!$D$6:$D$48) -> 200 | D8: =SUMIF('Suivi Agents'!$A$6:$A$48,$A8,'Suivi Agents'!$E$6:$E$48) -> 10 | E8: =SUMIF('Suivi Agents'!$A$6:$A$48,$A8,'Suivi Agents'!$F$6:$F$48) -> 210 | F8: =E8/Paramètres!$B$9 -> 9.5454545 | G8: =SUMIF('Suivi Agents'!$A$6:$A$48,$A8,'Suivi Agents'!$H$6:$H$48) -> 207 | H8: =SUMIF('Suivi Agents'!$A$6:$A$48,$A8,'Suivi Agents'!$K$6:$K$48) -> 0 | I8: =IF(E8>0,H8/E8,"") -> 0 | J8: =IF(E8>0,H8/(E8*Paramètres!$B$11/Paramètres!$B$9),"") -> 0 | K8: =SUM('Calcul quotidien'!D113:AH113) -> 0 | L8: =K8*Paramètres!$C$33 -> 0 | M8: =COUNTIFS('Suivi Agents'!$A$6:$A$48,$A8,'Suivi Agents'!$F$6:$F$48,">0") -> 4 | N8: =COUNTIFS('Suivi Agents'!$A$6:$A$48,$A8,'Suivi Agents'!$L$6:$L$48,">="&Paramètres!$C$31) -> 0 | O8: =IF(M8>0,N8/M8,0) -> 0 | P8: =IF(O8<Paramètres!$C$32,"Bloqué (activation)",INDEX(Paramètres!$A$26:$A$29,MATCH(I8,Paramètres!$B$26:$B$29,1))) -> Bloqué (activation) | Q8: =IF(O8<Paramètres!$C$32,0,INDEX(Paramètres!$C$26:$C$29,MATCH(I8,Paramètres!$B$26:$B$29,1))) -> 0 | R8: =RANK(W8,$W$6:$W$15) -> 3 | S8: =IF(AND(R8=1,I8>=Paramètres!$C$35),Paramètres!$C$34,0) -> 0 | T8: =L8+Q8 -> 0 | U8: 0.2 | V8: =(SUMIF('Suivi Agents'!$A$6:$A$48,$A8,'Suivi Agents'!$I$6:$I$48)*Paramètres!$C$38+SUMIF('Suivi Agents'!$A$6:$A$48,$A8,'Suivi Agents'!$J$6:$J$48)*Paramètres!$C$39)*U8 -> 0 | W8: =IF(E8>0,I8+H8/100000+(1000-ROW())/100000000,-1) -> 9.92e-06
A9: ZULU | C9: =SUMIF('Suivi Agents'!$A$6:$A$48,$A9,'Suivi Agents'!$D$6:$D$48) -> 100 | D9: =SUMIF('Suivi Agents'!$A$6:$A$48,$A9,'Suivi Agents'!$E$6:$E$48) -> 20 | E9: =SUMIF('Suivi Agents'!$A$6:$A$48,$A9,'Suivi Agents'!$F$6:$F$48) -> 120 | F9: =E9/Paramètres!$B$9 -> 5.4545455 | G9: =SUMIF('Suivi Agents'!$A$6:$A$48,$A9,'Suivi Agents'!$H$6:$H$48) -> 61 | H9: =SUMIF('Suivi Agents'!$A$6:$A$48,$A9,'Suivi Agents'!$K$6:$K$48) -> 0 | I9: =IF(E9>0,H9/E9,"") -> 0 | J9: =IF(E9>0,H9/(E9*Paramètres!$B$11/Paramètres!$B$9),"") -> 0 | K9: =SUM('Calcul quotidien'!D114:AH114) -> 0 | L9: =K9*Paramètres!$C$33 -> 0 | M9: =COUNTIFS('Suivi Agents'!$A$6:$A$48,$A9,'Suivi Agents'!$F$6:$F$48,">0") -> 2 | N9: =COUNTIFS('Suivi Agents'!$A$6:$A$48,$A9,'Suivi Agents'!$L$6:$L$48,">="&Paramètres!$C$31) -> 0 | O9: =IF(M9>0,N9/M9,0) -> 0 | P9: =IF(O9<Paramètres!$C$32,"Bloqué (activation)",INDEX(Paramètres!$A$26:$A$29,MATCH(I9,Paramètres!$B$26:$B$29,1))) -> Bloqué (activation) | Q9: =IF(O9<Paramètres!$C$32,0,INDEX(Paramètres!$C$26:$C$29,MATCH(I9,Paramètres!$B$26:$B$29,1))) -> 0 | R9: =RANK(W9,$W$6:$W$15) -> 4 | S9: =IF(AND(R9=1,I9>=Paramètres!$C$35),Paramètres!$C$34,0) -> 0 | T9: =L9+Q9 -> 0 | U9: 0.2 | V9: =(SUMIF('Suivi Agents'!$A$6:$A$48,$A9,'Suivi Agents'!$I$6:$I$48)*Paramètres!$C$38+SUMIF('Suivi Agents'!$A$6:$A$48,$A9,'Suivi Agents'!$J$6:$J$48)*Paramètres!$C$39)*U9 -> 0 | W9: =IF(E9>0,I9+H9/100000+(1000-ROW())/100000000,-1) -> 9.91e-06
A10: CHARLIE | C10: =SUMIF('Suivi Agents'!$A$6:$A$48,$A10,'Suivi Agents'!$D$6:$D$48) -> 70 | D10: =SUMIF('Suivi Agents'!$A$6:$A$48,$A10,'Suivi Agents'!$E$6:$E$48) -> 10 | E10: =SUMIF('Suivi Agents'!$A$6:$A$48,$A10,'Suivi Agents'!$F$6:$F$48) -> 80 | F10: =E10/Paramètres!$B$9 -> 3.6363636 | G10: =SUMIF('Suivi Agents'!$A$6:$A$48,$A10,'Suivi Agents'!$H$6:$H$48) -> 30 | H10: =SUMIF('Suivi Agents'!$A$6:$A$48,$A10,'Suivi Agents'!$K$6:$K$48) -> 0 | I10: =IF(E10>0,H10/E10,"") -> 0 | J10: =IF(E10>0,H10/(E10*Paramètres!$B$11/Paramètres!$B$9),"") -> 0 | K10: =SUM('Calcul quotidien'!D115:AH115) -> 0 | L10: =K10*Paramètres!$C$33 -> 0 | M10: =COUNTIFS('Suivi Agents'!$A$6:$A$48,$A10,'Suivi Agents'!$F$6:$F$48,">0") -> 2 | N10: =COUNTIFS('Suivi Agents'!$A$6:$A$48,$A10,'Suivi Agents'!$L$6:$L$48,">="&Paramètres!$C$31) -> 0 | O10: =IF(M10>0,N10/M10,0) -> 0 | P10: =IF(O10<Paramètres!$C$32,"Bloqué (activation)",INDEX(Paramètres!$A$26:$A$29,MATCH(I10,Paramètres!$B$26:$B$29,1))) -> Bloqué (activation) | Q10: =IF(O10<Paramètres!$C$32,0,INDEX(Paramètres!$C$26:$C$29,MATCH(I10,Paramètres!$B$26:$B$29,1))) -> 0 | R10: =RANK(W10,$W$6:$W$15) -> 5 | S10: =IF(AND(R10=1,I10>=Paramètres!$C$35),Paramètres!$C$34,0) -> 0 | T10: =L10+Q10 -> 0 | U10: 0.2 | V10: =(SUMIF('Suivi Agents'!$A$6:$A$48,$A10,'Suivi Agents'!$I$6:$I$48)*Paramètres!$C$38+SUMIF('Suivi Agents'!$A$6:$A$48,$A10,'Suivi Agents'!$J$6:$J$48)*Paramètres!$C$39)*U10 -> 0 | W10: =IF(E10>0,I10+H10/100000+(1000-ROW())/100000000,-1) -> 9.9e-06
A11: MIKE | C11: =SUMIF('Suivi Agents'!$A$6:$A$48,$A11,'Suivi Agents'!$D$6:$D$48) -> 120 | D11: =SUMIF('Suivi Agents'!$A$6:$A$48,$A11,'Suivi Agents'!$E$6:$E$48) -> 10 | E11: =SUMIF('Suivi Agents'!$A$6:$A$48,$A11,'Suivi Agents'!$F$6:$F$48) -> 130 | F11: =E11/Paramètres!$B$9 -> 5.9090909 | G11: =SUMIF('Suivi Agents'!$A$6:$A$48,$A11,'Suivi Agents'!$H$6:$H$48) -> 151 | H11: =SUMIF('Suivi Agents'!$A$6:$A$48,$A11,'Suivi Agents'!$K$6:$K$48) -> 0 | I11: =IF(E11>0,H11/E11,"") -> 0 | J11: =IF(E11>0,H11/(E11*Paramètres!$B$11/Paramètres!$B$9),"") -> 0 | K11: =SUM('Calcul quotidien'!D116:AH116) -> 0 | L11: =K11*Paramètres!$C$33 -> 0 | M11: =COUNTIFS('Suivi Agents'!$A$6:$A$48,$A11,'Suivi Agents'!$F$6:$F$48,">0") -> 4 | N11: =COUNTIFS('Suivi Agents'!$A$6:$A$48,$A11,'Suivi Agents'!$L$6:$L$48,">="&Paramètres!$C$31) -> 0 | O11: =IF(M11>0,N11/M11,0) -> 0 | P11: =IF(O11<Paramètres!$C$32,"Bloqué (activation)",INDEX(Paramètres!$A$26:$A$29,MATCH(I11,Paramètres!$B$26:$B$29,1))) -> Bloqué (activation) | Q11: =IF(O11<Paramètres!$C$32,0,INDEX(Paramètres!$C$26:$C$29,MATCH(I11,Paramètres!$B$26:$B$29,1))) -> 0 | R11: =RANK(W11,$W$6:$W$15) -> 6 | S11: =IF(AND(R11=1,I11>=Paramètres!$C$35),Paramètres!$C$34,0) -> 0 | T11: =L11+Q11 -> 0 | U11: 0.2 | V11: =(SUMIF('Suivi Agents'!$A$6:$A$48,$A11,'Suivi Agents'!$I$6:$I$48)*Paramètres!$C$38+SUMIF('Suivi Agents'!$A$6:$A$48,$A11,'Suivi Agents'!$J$6:$J$48)*Paramètres!$C$39)*U11 -> 0 | W11: =IF(E11>0,I11+H11/100000+(1000-ROW())/100000000,-1) -> 9.89e-06
A12: ANONYMAT | C12: =SUMIF('Suivi Agents'!$A$6:$A$48,$A12,'Suivi Agents'!$D$6:$D$48) -> 120 | D12: =SUMIF('Suivi Agents'!$A$6:$A$48,$A12,'Suivi Agents'!$E$6:$E$48) -> 20 | E12: =SUMIF('Suivi Agents'!$A$6:$A$48,$A12,'Suivi Agents'!$F$6:$F$48) -> 140 | F12: =E12/Paramètres!$B$9 -> 6.3636364 | G12: =SUMIF('Suivi Agents'!$A$6:$A$48,$A12,'Suivi Agents'!$H$6:$H$48) -> 76 | H12: =SUMIF('Suivi Agents'!$A$6:$A$48,$A12,'Suivi Agents'!$K$6:$K$48) -> 0 | I12: =IF(E12>0,H12/E12,"") -> 0 | J12: =IF(E12>0,H12/(E12*Paramètres!$B$11/Paramètres!$B$9),"") -> 0 | K12: =SUM('Calcul quotidien'!D117:AH117) -> 0 | L12: =K12*Paramètres!$C$33 -> 0 | M12: =COUNTIFS('Suivi Agents'!$A$6:$A$48,$A12,'Suivi Agents'!$F$6:$F$48,">0") -> 4 | N12: =COUNTIFS('Suivi Agents'!$A$6:$A$48,$A12,'Suivi Agents'!$L$6:$L$48,">="&Paramètres!$C$31) -> 0 | O12: =IF(M12>0,N12/M12,0) -> 0 | P12: =IF(O12<Paramètres!$C$32,"Bloqué (activation)",INDEX(Paramètres!$A$26:$A$29,MATCH(I12,Paramètres!$B$26:$B$29,1))) -> Bloqué (activation) | Q12: =IF(O12<Paramètres!$C$32,0,INDEX(Paramètres!$C$26:$C$29,MATCH(I12,Paramètres!$B$26:$B$29,1))) -> 0 | R12: =RANK(W12,$W$6:$W$15) -> 7 | S12: =IF(AND(R12=1,I12>=Paramètres!$C$35),Paramètres!$C$34,0) -> 0 | T12: =L12+Q12 -> 0 | U12: 0 | V12: =(SUMIF('Suivi Agents'!$A$6:$A$48,$A12,'Suivi Agents'!$I$6:$I$48)*Paramètres!$C$38+SUMIF('Suivi Agents'!$A$6:$A$48,$A12,'Suivi Agents'!$J$6:$J$48)*Paramètres!$C$39)*U12 -> 0 | W12: =IF(E12>0,I12+H12/100000+(1000-ROW())/100000000,-1) -> 9.88e-06
A13: CONCORDE | C13: =SUMIF('Suivi Agents'!$A$6:$A$48,$A13,'Suivi Agents'!$D$6:$D$48) -> 157 | D13: =SUMIF('Suivi Agents'!$A$6:$A$48,$A13,'Suivi Agents'!$E$6:$E$48) -> 10 | E13: =SUMIF('Suivi Agents'!$A$6:$A$48,$A13,'Suivi Agents'!$F$6:$F$48) -> 167 | F13: =E13/Paramètres!$B$9 -> 7.5909091 | G13: =SUMIF('Suivi Agents'!$A$6:$A$48,$A13,'Suivi Agents'!$H$6:$H$48) -> 151 | H13: =SUMIF('Suivi Agents'!$A$6:$A$48,$A13,'Suivi Agents'!$K$6:$K$48) -> 0 | I13: =IF(E13>0,H13/E13,"") -> 0 | J13: =IF(E13>0,H13/(E13*Paramètres!$B$11/Paramètres!$B$9),"") -> 0 | K13: =SUM('Calcul quotidien'!D118:AH118) -> 0 | L13: =K13*Paramètres!$C$33 -> 0 | M13: =COUNTIFS('Suivi Agents'!$A$6:$A$48,$A13,'Suivi Agents'!$F$6:$F$48,">0") -> 5 | N13: =COUNTIFS('Suivi Agents'!$A$6:$A$48,$A13,'Suivi Agents'!$L$6:$L$48,">="&Paramètres!$C$31) -> 0 | O13: =IF(M13>0,N13/M13,0) -> 0 | P13: =IF(O13<Paramètres!$C$32,"Bloqué (activation)",INDEX(Paramètres!$A$26:$A$29,MATCH(I13,Paramètres!$B$26:$B$29,1))) -> Bloqué (activation) | Q13: =IF(O13<Paramètres!$C$32,0,INDEX(Paramètres!$C$26:$C$29,MATCH(I13,Paramètres!$B$26:$B$29,1))) -> 0 | R13: =RANK(W13,$W$6:$W$15) -> 8 | S13: =IF(AND(R13=1,I13>=Paramètres!$C$35),Paramètres!$C$34,0) -> 0 | T13: =L13+Q13 -> 0 | U13: 0.2 | V13: =(SUMIF('Suivi Agents'!$A$6:$A$48,$A13,'Suivi Agents'!$I$6:$I$48)*Paramètres!$C$38+SUMIF('Suivi Agents'!$A$6:$A$48,$A13,'Suivi Agents'!$J$6:$J$48)*Paramètres!$C$39)*U13 -> 0 | W13: =IF(E13>0,I13+H13/100000+(1000-ROW())/100000000,-1) -> 9.87e-06
A14: BRAVO | C14: =SUMIF('Suivi Agents'!$A$6:$A$48,$A14,'Suivi Agents'!$D$6:$D$48) -> 60 | D14: =SUMIF('Suivi Agents'!$A$6:$A$48,$A14,'Suivi Agents'!$E$6:$E$48) -> 40 | E14: =SUMIF('Suivi Agents'!$A$6:$A$48,$A14,'Suivi Agents'!$F$6:$F$48) -> 100 | F14: =E14/Paramètres!$B$9 -> 4.5454545 | G14: =SUMIF('Suivi Agents'!$A$6:$A$48,$A14,'Suivi Agents'!$H$6:$H$48) -> 1 | H14: =SUMIF('Suivi Agents'!$A$6:$A$48,$A14,'Suivi Agents'!$K$6:$K$48) -> 0 | I14: =IF(E14>0,H14/E14,"") -> 0 | J14: =IF(E14>0,H14/(E14*Paramètres!$B$11/Paramètres!$B$9),"") -> 0 | K14: =SUM('Calcul quotidien'!D119:AH119) -> 0 | L14: =K14*Paramètres!$C$33 -> 0 | M14: =COUNTIFS('Suivi Agents'!$A$6:$A$48,$A14,'Suivi Agents'!$F$6:$F$48,">0") -> 2 | N14: =COUNTIFS('Suivi Agents'!$A$6:$A$48,$A14,'Suivi Agents'!$L$6:$L$48,">="&Paramètres!$C$31) -> 0 | O14: =IF(M14>0,N14/M14,0) -> 0 | P14: =IF(O14<Paramètres!$C$32,"Bloqué (activation)",INDEX(Paramètres!$A$26:$A$29,MATCH(I14,Paramètres!$B$26:$B$29,1))) -> Bloqué (activation) | Q14: =IF(O14<Paramètres!$C$32,0,INDEX(Paramètres!$C$26:$C$29,MATCH(I14,Paramètres!$B$26:$B$29,1))) -> 0 | R14: =RANK(W14,$W$6:$W$15) -> 9 | S14: =IF(AND(R14=1,I14>=Paramètres!$C$35),Paramètres!$C$34,0) -> 0 | T14: =L14+Q14 -> 0 | U14: 0.2 | V14: =(SUMIF('Suivi Agents'!$A$6:$A$48,$A14,'Suivi Agents'!$I$6:$I$48)*Paramètres!$C$38+SUMIF('Suivi Agents'!$A$6:$A$48,$A14,'Suivi Agents'!$J$6:$J$48)*Paramètres!$C$39)*U14 -> 0 | W14: =IF(E14>0,I14+H14/100000+(1000-ROW())/100000000,-1) -> 9.86e-06
A15: OMEGA | C15: =SUMIF('Suivi Agents'!$A$6:$A$48,$A15,'Suivi Agents'!$D$6:$D$48) -> 60 | D15: =SUMIF('Suivi Agents'!$A$6:$A$48,$A15,'Suivi Agents'!$E$6:$E$48) -> 40 | E15: =SUMIF('Suivi Agents'!$A$6:$A$48,$A15,'Suivi Agents'!$F$6:$F$48) -> 100 | F15: =E15/Paramètres!$B$9 -> 4.5454545 | G15: =SUMIF('Suivi Agents'!$A$6:$A$48,$A15,'Suivi Agents'!$H$6:$H$48) -> 0 | H15: =SUMIF('Suivi Agents'!$A$6:$A$48,$A15,'Suivi Agents'!$K$6:$K$48) -> 0 | I15: =IF(E15>0,H15/E15,"") -> 0 | J15: =IF(E15>0,H15/(E15*Paramètres!$B$11/Paramètres!$B$9),"") -> 0 | K15: =SUM('Calcul quotidien'!D120:AH120) -> 0 | L15: =K15*Paramètres!$C$33 -> 0 | M15: =COUNTIFS('Suivi Agents'!$A$6:$A$48,$A15,'Suivi Agents'!$F$6:$F$48,">0") -> 3 | N15: =COUNTIFS('Suivi Agents'!$A$6:$A$48,$A15,'Suivi Agents'!$L$6:$L$48,">="&Paramètres!$C$31) -> 0 | O15: =IF(M15>0,N15/M15,0) -> 0 | P15: =IF(O15<Paramètres!$C$32,"Bloqué (activation)",INDEX(Paramètres!$A$26:$A$29,MATCH(I15,Paramètres!$B$26:$B$29,1))) -> Bloqué (activation) | Q15: =IF(O15<Paramètres!$C$32,0,INDEX(Paramètres!$C$26:$C$29,MATCH(I15,Paramètres!$B$26:$B$29,1))) -> 0 | R15: =RANK(W15,$W$6:$W$15) -> 10 | S15: =IF(AND(R15=1,I15>=Paramètres!$C$35),Paramètres!$C$34,0) -> 0 | T15: =L15+Q15 -> 0 | U15: 0.2 | V15: =(SUMIF('Suivi Agents'!$A$6:$A$48,$A15,'Suivi Agents'!$I$6:$I$48)*Paramètres!$C$38+SUMIF('Suivi Agents'!$A$6:$A$48,$A15,'Suivi Agents'!$J$6:$J$48)*Paramètres!$C$39)*U15 -> 0 | W15: =IF(E15>0,I15+H15/100000+(1000-ROW())/100000000,-1) -> 9.85e-06
A16: TOTAL | C16: =SUM(C6:C15) -> 1247 | D16: =SUM(D6:D15) -> 240 | E16: =SUM(E6:E15) -> 1487 | F16: =SUM(F6:F15) -> 67.590909 | G16: =SUM(G6:G15) -> 1167 | H16: =SUM(H6:H15) -> 0 | I16: =IF(E16>0,H16/E16,"") -> 0 | J16: =IF(E16>0,H16/(E16*Paramètres!$B$11/Paramètres!$B$9),"") -> 0 | K16: =SUM(K6:K15) -> 0 | L16: =SUM(L6:L15) -> 0 | M16: =SUM(M6:M15) -> 41 | N16: =SUM(N6:N15) -> 0 | Q16: =SUM(Q6:Q15) -> 0 | S16: =SUM(S6:S15) -> 0 | T16: =SUM(T6:T15) -> 0 | V16: =SUM(V6:V15) -> 0

Sheet Classement
A1: Classement du mois
A2: Top 10 des agents éligibles et classement des équipes, par TRO cumulé.
A4: Rang | B4: Agent | C4: Équipe | D4: Réalisé | E4: Objectif | F4: TRO | G4: Palier
A5: 1 | B5: =IFERROR(INDEX('Suivi Agents'!$B$6:$B$48,MATCH(A5,'Suivi Agents'!$X$6:$X$48,0)),"") -> pms_rgz_tosee.ftth | C5: =IFERROR(INDEX('Suivi Agents'!$A$6:$A$48,MATCH(A5,'Suivi Agents'!$X$6:$X$48,0)),"") -> YANKEE | D5: =IFERROR(INDEX('Suivi Agents'!$K$6:$K$48,MATCH(A5,'Suivi Agents'!$X$6:$X$48,0)),"") -> 0 | E5: =IFERROR(INDEX('Suivi Agents'!$F$6:$F$48,MATCH(A5,'Suivi Agents'!$X$6:$X$48,0)),"") -> 44 | F5: =IFERROR(INDEX('Suivi Agents'!$L$6:$L$48,MATCH(A5,'Suivi Agents'!$X$6:$X$48,0)),"") -> 0 | G5: =IFERROR(INDEX('Suivi Agents'!$R$6:$R$48,MATCH(A5,'Suivi Agents'!$X$6:$X$48,0)),"") -> Aucun
A6: 2 | B6: =IFERROR(INDEX('Suivi Agents'!$B$6:$B$48,MATCH(A6,'Suivi Agents'!$X$6:$X$48,0)),"") -> pvt_rgz_mfrancois.ftth | C6: =IFERROR(INDEX('Suivi Agents'!$A$6:$A$48,MATCH(A6,'Suivi Agents'!$X$6:$X$48,0)),"") -> YANKEE | D6: =IFERROR(INDEX('Suivi Agents'!$K$6:$K$48,MATCH(A6,'Suivi Agents'!$X$6:$X$48,0)),"") -> 0 | E6: =IFERROR(INDEX('Suivi Agents'!$F$6:$F$48,MATCH(A6,'Suivi Agents'!$X$6:$X$48,0)),"") -> 35 | F6: =IFERROR(INDEX('Suivi Agents'!$L$6:$L$48,MATCH(A6,'Suivi Agents'!$X$6:$X$48,0)),"") -> 0 | G6: =IFERROR(INDEX('Suivi Agents'!$R$6:$R$48,MATCH(A6,'Suivi Agents'!$X$6:$X$48,0)),"") -> Aucun
A7: 3 | B7: =IFERROR(INDEX('Suivi Agents'!$B$6:$B$48,MATCH(A7,'Suivi Agents'!$X$6:$X$48,0)),"") -> pvt_rgz_fadji.ftth | C7: =IFERROR(INDEX('Suivi Agents'!$A$6:$A$48,MATCH(A7,'Suivi Agents'!$X$6:$X$48,0)),"") -> YANKEE | D7: =IFERROR(INDEX('Suivi Agents'!$K$6:$K$48,MATCH(A7,'Suivi Agents'!$X$6:$X$48,0)),"") -> 0 | E7: =IFERROR(INDEX('Suivi Agents'!$F$6:$F$48,MATCH(A7,'Suivi Agents'!$X$6:$X$48,0)),"") -> 34 | F7: =IFERROR(INDEX('Suivi Agents'!$L$6:$L$48,MATCH(A7,'Suivi Agents'!$X$6:$X$48,0)),"") -> 0 | G7: =IFERROR(INDEX('Suivi Agents'!$R$6:$R$48,MATCH(A7,'Suivi Agents'!$X$6:$X$48,0)),"") -> Aucun
A8: 4 | B8: =IFERROR(INDEX('Suivi Agents'!$B$6:$B$48,MATCH(A8,'Suivi Agents'!$X$6:$X$48,0)),"") -> pvt_rgz_dcharmelie.ftth | C8: =IFERROR(INDEX('Suivi Agents'!$A$6:$A$48,MATCH(A8,'Suivi Agents'!$X$6:$X$48,0)),"") -> YANKEE | D8: =IFERROR(INDEX('Suivi Agents'!$K$6:$K$48,MATCH(A8,'Suivi Agents'!$X$6:$X$48,0)),"") -> 0 | E8: =IFERROR(INDEX('Suivi Agents'!$F$6:$F$48,MATCH(A8,'Suivi Agents'!$X$6:$X$48,0)),"") -> 28 | F8: =IFERROR(INDEX('Suivi Agents'!$L$6:$L$48,MATCH(A8,'Suivi Agents'!$X$6:$X$48,0)),"") -> 0 | G8: =IFERROR(INDEX('Suivi Agents'!$R$6:$R$48,MATCH(A8,'Suivi Agents'!$X$6:$X$48,0)),"") -> Aucun
A9: 5 | B9: =IFERROR(INDEX('Suivi Agents'!$B$6:$B$48,MATCH(A9,'Suivi Agents'!$X$6:$X$48,0)),"") -> pvt_rgz_gkohla.ftth | C9: =IFERROR(INDEX('Suivi Agents'!$A$6:$A$48,MATCH(A9,'Suivi Agents'!$X$6:$X$48,0)),"") -> YANKEE | D9: =IFERROR(INDEX('Suivi Agents'!$K$6:$K$48,MATCH(A9,'Suivi Agents'!$X$6:$X$48,0)),"") -> 0 | E9: =IFERROR(INDEX('Suivi Agents'!$F$6:$F$48,MATCH(A9,'Suivi Agents'!$X$6:$X$48,0)),"") -> 36 | F9: =IFERROR(INDEX('Suivi Agents'!$L$6:$L$48,MATCH(A9,'Suivi Agents'!$X$6:$X$48,0)),"") -> 0 | G9: =IFERROR(INDEX('Suivi Agents'!$R$6:$R$48,MATCH(A9,'Suivi Agents'!$X$6:$X$48,0)),"") -> Aucun
A10: 6 | B10: =IFERROR(INDEX('Suivi Agents'!$B$6:$B$48,MATCH(A10,'Suivi Agents'!$X$6:$X$48,0)),"") -> pvt_rgz_rclotoe.ftth | C10: =IFERROR(INDEX('Suivi Agents'!$A$6:$A$48,MATCH(A10,'Suivi Agents'!$X$6:$X$48,0)),"") -> YANKEE | D10: =IFERROR(INDEX('Suivi Agents'!$K$6:$K$48,MATCH(A10,'Suivi Agents'!$X$6:$X$48,0)),"") -> 0 | E10: =IFERROR(INDEX('Suivi Agents'!$F$6:$F$48,MATCH(A10,'Suivi Agents'!$X$6:$X$48,0)),"") -> 30 | F10: =IFERROR(INDEX('Suivi Agents'!$L$6:$L$48,MATCH(A10,'Suivi Agents'!$X$6:$X$48,0)),"") -> 0 | G10: =IFERROR(INDEX('Suivi Agents'!$R$6:$R$48,MATCH(A10,'Suivi Agents'!$X$6:$X$48,0)),"") -> Aucun
A11: 7 | B11: =IFERROR(INDEX('Suivi Agents'!$B$6:$B$48,MATCH(A11,'Suivi Agents'!$X$6:$X$48,0)),"") -> pvt_rgz_aconstant.ftth | C11: =IFERROR(INDEX('Suivi Agents'!$A$6:$A$48,MATCH(A11,'Suivi Agents'!$X$6:$X$48,0)),"") -> YANKEE | D11: =IFERROR(INDEX('Suivi Agents'!$K$6:$K$48,MATCH(A11,'Suivi Agents'!$X$6:$X$48,0)),"") -> 0 | E11: =IFERROR(INDEX('Suivi Agents'!$F$6:$F$48,MATCH(A11,'Suivi Agents'!$X$6:$X$48,0)),"") -> 25 | F11: =IFERROR(INDEX('Suivi Agents'!$L$6:$L$48,MATCH(A11,'Suivi Agents'!$X$6:$X$48,0)),"") -> 0 | G11: =IFERROR(INDEX('Suivi Agents'!$R$6:$R$48,MATCH(A11,'Suivi Agents'!$X$6:$X$48,0)),"") -> Aucun
A12: 8 | B12: =IFERROR(INDEX('Suivi Agents'!$B$6:$B$48,MATCH(A12,'Suivi Agents'!$X$6:$X$48,0)),"") -> pvt_rgz_cmessinou.ftth | C12: =IFERROR(INDEX('Suivi Agents'!$A$6:$A$48,MATCH(A12,'Suivi Agents'!$X$6:$X$48,0)),"") -> YANKEE | D12: =IFERROR(INDEX('Suivi Agents'!$K$6:$K$48,MATCH(A12,'Suivi Agents'!$X$6:$X$48,0)),"") -> 0 | E12: =IFERROR(INDEX('Suivi Agents'!$F$6:$F$48,MATCH(A12,'Suivi Agents'!$X$6:$X$48,0)),"") -> 23 | F12: =IFERROR(INDEX('Suivi Agents'!$L$6:$L$48,MATCH(A12,'Suivi Agents'!$X$6:$X$48,0)),"") -> 0 | G12: =IFERROR(INDEX('Suivi Agents'!$R$6:$R$48,MATCH(A12,'Suivi Agents'!$X$6:$X$48,0)),"") -> Aucun
A13: 9 | B13: =IFERROR(INDEX('Suivi Agents'!$B$6:$B$48,MATCH(A13,'Suivi Agents'!$X$6:$X$48,0)),"") -> pvt_rgz_lsenakpon.ftth | C13: =IFERROR(INDEX('Suivi Agents'!$A$6:$A$48,MATCH(A13,'Suivi Agents'!$X$6:$X$48,0)),"") -> YANKEE | D13: =IFERROR(INDEX('Suivi Agents'!$K$6:$K$48,MATCH(A13,'Suivi Agents'!$X$6:$X$48,0)),"") -> 0 | E13: =IFERROR(INDEX('Suivi Agents'!$F$6:$F$48,MATCH(A13,'Suivi Agents'!$X$6:$X$48,0)),"") -> 40 | F13: =IFERROR(INDEX('Suivi Agents'!$L$6:$L$48,MATCH(A13,'Suivi Agents'!$X$6:$X$48,0)),"") -> 0 | G13: =IFERROR(INDEX('Suivi Agents'!$R$6:$R$48,MATCH(A13,'Suivi Agents'!$X$6:$X$48,0)),"") -> Aucun
A14: 10 | B14: =IFERROR(INDEX('Suivi Agents'!$B$6:$B$48,MATCH(A14,'Suivi Agents'!$X$6:$X$48,0)),"") -> pvt_rgz_tletitia.ftth | C14: =IFERROR(INDEX('Suivi Agents'!$A$6:$A$48,MATCH(A14,'Suivi Agents'!$X$6:$X$48,0)),"") -> YANKEE | D14: =IFERROR(INDEX('Suivi Agents'!$K$6:$K$48,MATCH(A14,'Suivi Agents'!$X$6:$X$48,0)),"") -> 0 | E14: =IFERROR(INDEX('Suivi Agents'!$F$6:$F$48,MATCH(A14,'Suivi Agents'!$X$6:$X$48,0)),"") -> 20 | F14: =IFERROR(INDEX('Suivi Agents'!$L$6:$L$48,MATCH(A14,'Suivi Agents'!$X$6:$X$48,0)),"") -> 0 | G14: =IFERROR(INDEX('Suivi Agents'!$R$6:$R$48,MATCH(A14,'Suivi Agents'!$X$6:$X$48,0)),"") -> Aucun
A17: Rang | B17: Équipe | C17: Superviseur | D17: Réalisé | E17: Objectif | F17: TRO | G17: Palier superviseur
A18: 1 | B18: =IFERROR(INDEX('Suivi Équipes'!$A$6:$A$15,MATCH(A18,'Suivi Équipes'!$R$6:$R$15,0)),"") -> YANKEE | C18: =IFERROR(INDEX('Suivi Équipes'!$B$6:$B$15,MATCH(A18,'Suivi Équipes'!$R$6:$R$15,0))&"","") | D18: =IFERROR(INDEX('Suivi Équipes'!$H$6:$H$15,MATCH(A18,'Suivi Équipes'!$R$6:$R$15,0)),"") -> 0 | E18: =IFERROR(INDEX('Suivi Équipes'!$E$6:$E$15,MATCH(A18,'Suivi Équipes'!$R$6:$R$15,0)),"") -> 340 | F18: =IFERROR(INDEX('Suivi Équipes'!$I$6:$I$15,MATCH(A18,'Suivi Équipes'!$R$6:$R$15,0)),"") -> 0 | G18: =IFERROR(INDEX('Suivi Équipes'!$P$6:$P$15,MATCH(A18,'Suivi Équipes'!$R$6:$R$15,0)),"") -> Bloqué (activation)
A19: 2 | B19: =IFERROR(INDEX('Suivi Équipes'!$A$6:$A$15,MATCH(A19,'Suivi Équipes'!$R$6:$R$15,0)),"") -> ALPHA | C19: =IFERROR(INDEX('Suivi Équipes'!$B$6:$B$15,MATCH(A19,'Suivi Équipes'!$R$6:$R$15,0))&"","") | D19: =IFERROR(INDEX('Suivi Équipes'!$H$6:$H$15,MATCH(A19,'Suivi Équipes'!$R$6:$R$15,0)),"") -> 0 | E19: =IFERROR(INDEX('Suivi Équipes'!$E$6:$E$15,MATCH(A19,'Suivi Équipes'!$R$6:$R$15,0)),"") -> 100 | F19: =IFERROR(INDEX('Suivi Équipes'!$I$6:$I$15,MATCH(A19,'Suivi Équipes'!$R$6:$R$15,0)),"") -> 0 | G19: =IFERROR(INDEX('Suivi Équipes'!$P$6:$P$15,MATCH(A19,'Suivi Équipes'!$R$6:$R$15,0)),"") -> Bloqué (activation)
A20: 3 | B20: =IFERROR(INDEX('Suivi Équipes'!$A$6:$A$15,MATCH(A20,'Suivi Équipes'!$R$6:$R$15,0)),"") -> TANGO | C20: =IFERROR(INDEX('Suivi Équipes'!$B$6:$B$15,MATCH(A20,'Suivi Équipes'!$R$6:$R$15,0))&"","") | D20: =IFERROR(INDEX('Suivi Équipes'!$H$6:$H$15,MATCH(A20,'Suivi Équipes'!$R$6:$R$15,0)),"") -> 0 | E20: =IFERROR(INDEX('Suivi Équipes'!$E$6:$E$15,MATCH(A20,'Suivi Équipes'!$R$6:$R$15,0)),"") -> 210 | F20: =IFERROR(INDEX('Suivi Équipes'!$I$6:$I$15,MATCH(A20,'Suivi Équipes'!$R$6:$R$15,0)),"") -> 0 | G20: =IFERROR(INDEX('Suivi Équipes'!$P$6:$P$15,MATCH(A20,'Suivi Équipes'!$R$6:$R$15,0)),"") -> Bloqué (activation)
A21: 4 | B21: =IFERROR(INDEX('Suivi Équipes'!$A$6:$A$15,MATCH(A21,'Suivi Équipes'!$R$6:$R$15,0)),"") -> ZULU | C21: =IFERROR(INDEX('Suivi Équipes'!$B$6:$B$15,MATCH(A21,'Suivi Équipes'!$R$6:$R$15,0))&"","") | D21: =IFERROR(INDEX('Suivi Équipes'!$H$6:$H$15,MATCH(A21,'Suivi Équipes'!$R$6:$R$15,0)),"") -> 0 | E21: =IFERROR(INDEX('Suivi Équipes'!$E$6:$E$15,MATCH(A21,'Suivi Équipes'!$R$6:$R$15,0)),"") -> 120 | F21: =IFERROR(INDEX('Suivi Équipes'!$I$6:$I$15,MATCH(A21,'Suivi Équipes'!$R$6:$R$15,0)),"") -> 0 | G21: =IFERROR(INDEX('Suivi Équipes'!$P$6:$P$15,MATCH(A21,'Suivi Équipes'!$R$6:$R$15,0)),"") -> Bloqué (activation)
A22: 5 | B22: =IFERROR(INDEX('Suivi Équipes'!$A$6:$A$15,MATCH(A22,'Suivi Équipes'!$R$6:$R$15,0)),"") -> CHARLIE | C22: =IFERROR(INDEX('Suivi Équipes'!$B$6:$B$15,MATCH(A22,'Suivi Équipes'!$R$6:$R$15,0))&"","") | D22: =IFERROR(INDEX('Suivi Équipes'!$H$6:$H$15,MATCH(A22,'Suivi Équipes'!$R$6:$R$15,0)),"") -> 0 | E22: =IFERROR(INDEX('Suivi Équipes'!$E$6:$E$15,MATCH(A22,'Suivi Équipes'!$R$6:$R$15,0)),"") -> 80 | F22: =IFERROR(INDEX('Suivi Équipes'!$I$6:$I$15,MATCH(A22,'Suivi Équipes'!$R$6:$R$15,0)),"") -> 0 | G22: =IFERROR(INDEX('Suivi Équipes'!$P$6:$P$15,MATCH(A22,'Suivi Équipes'!$R$6:$R$15,0)),"") -> Bloqué (activation)
A23: 6 | B23: =IFERROR(INDEX('Suivi Équipes'!$A$6:$A$15,MATCH(A23,'Suivi Équipes'!$R$6:$R$15,0)),"") -> MIKE | C23: =IFERROR(INDEX('Suivi Équipes'!$B$6:$B$15,MATCH(A23,'Suivi Équipes'!$R$6:$R$15,0))&"","") | D23: =IFERROR(INDEX('Suivi Équipes'!$H$6:$H$15,MATCH(A23,'Suivi Équipes'!$R$6:$R$15,0)),"") -> 0 | E23: =IFERROR(INDEX('Suivi Équipes'!$E$6:$E$15,MATCH(A23,'Suivi Équipes'!$R$6:$R$15,0)),"") -> 130 | F23: =IFERROR(INDEX('Suivi Équipes'!$I$6:$I$15,MATCH(A23,'Suivi Équipes'!$R$6:$R$15,0)),"") -> 0 | G23: =IFERROR(INDEX('Suivi Équipes'!$P$6:$P$15,MATCH(A23,'Suivi Équipes'!$R$6:$R$15,0)),"") -> Bloqué (activation)
