Workbook

Sheet Paramètres
A1: Point du jour : lundi 12 octobre 2026
A2: Cellules jaunes modifiables. Les autres onglets se recalculent.
A4: Date du point | B4: 12/10/2026
A5: Jours ouvrés en octobre | B5: 22 | C5: Lundi à vendredi, comme dans le plan de motivation. Le fichier objectifs_octobre_2026.xlsx divise par 20.
A6: Prime journée réussie (agent) | B6: 200
A7: Prime champion du jour | B7: 1000
A8: Prime journée équipe réussie (superviseur) | B8: 500
A11: Sources
A12: Objectifs mensuels : objectifs_octobre_2026.xlsx, onglet OBJECTIFS TRACKING (1 487 ventes).
A13: Ventes du 12/10 : point par login transmis par GZ (capture « Total RGZ » = 45 ventes, sans détail B2C/B2B).

Sheet Agents 12-10
A1: Agents : performance du 12 octobre
A2: Saisir uniquement la colonne « Ventes du jour » (jaune). Objectif du jour = objectif du mois / jours ouvrés.
A4: Équipe | B4: Login | C4: Obj. du mois | D4: Obj. du jour | E4: Ventes du jour | F4: Réalisation | G4: Objectif du jour atteint | H4: Champion du jour | I4: Prime journée (FCFA) | J4: Prime champion (FCFA) | K4: Total primes du jour (FCFA) | L4: score
A5: YANKEE | B5: pms_rgz_tosee.ftth | C5: 44 | D5: =IF(C5>0,C5/Paramètres!$B$5,"") -> 2 | E5: 0 | F5: =IF(C5>0,E5/D5,"") -> 0 | G5: =IF(C5>0,IF(E5>=D5,"Oui","Non"),"Sans objectif") -> Non | H5: =IF(AND(L5>0,L5=MAX($L$5:$L$48)),"Champion","") | I5: =IF(G5="Oui",Paramètres!$B$6,0) -> 0 | J5: =IF(H5="Champion",Paramètres!$B$7,0) -> 0 | K5: =I5+J5 -> 0 | L5: =IF(G5="Oui",F5+E5/1000+(1000-ROW())/10000000,-1) -> -1
A6: YANKEE | B6: pvt_rgz_mfrancois.ftth | C6: 35 | D6: =IF(C6>0,C6/Paramètres!$B$5,"") -> 1.5909091 | E6: 3 | F6: =IF(C6>0,E6/D6,"") -> 1.8857143 | G6: =IF(C6>0,IF(E6>=D6,"Oui","Non"),"Sans objectif") -> Oui | H6: =IF(AND(L6>0,L6=MAX($L$5:$L$48)),"Champion","") | I6: =IF(G6="Oui",Paramètres!$B$6,0) -> 200 | J6: =IF(H6="Champion",Paramètres!$B$7,0) -> 0 | K6: =I6+J6 -> 200 | L6: =IF(G6="Oui",F6+E6/1000+(1000-ROW())/10000000,-1) -> 1.8888137
A7: YANKEE | B7: pvt_rgz_fadji.ftth | C7: 34 | D7: =IF(C7>0,C7/Paramètres!$B$5,"") -> 1.5454545 | E7: 0 | F7: =IF(C7>0,E7/D7,"") -> 0 | G7: =IF(C7>0,IF(E7>=D7,"Oui","Non"),"Sans objectif") -> Non | H7: =IF(AND(L7>0,L7=MAX($L$5:$L$48)),"Champion","") | I7: =IF(G7="Oui",Paramètres!$B$6,0) -> 0 | J7: =IF(H7="Champion",Paramètres!$B$7,0) -> 0 | K7: =I7+J7 -> 0 | L7: =IF(G7="Oui",F7+E7/1000+(1000-ROW())/10000000,-1) -> -1
A8: YANKEE | B8: pvt_rgz_dcharmelie.ftth | C8: 28 | D8: =IF(C8>0,C8/Paramètres!$B$5,"") -> 1.2727273 | E8: 0 | F8: =IF(C8>0,E8/D8,"") -> 0 | G8: =IF(C8>0,IF(E8>=D8,"Oui","Non"),"Sans objectif") -> Non | H8: =IF(AND(L8>0,L8=MAX($L$5:$L$48)),"Champion","") | I8: =IF(G8="Oui",Paramètres!$B$6,0) -> 0 | J8: =IF(H8="Champion",Paramètres!$B$7,0) -> 0 | K8: =I8+J8 -> 0 | L8: =IF(G8="Oui",F8+E8/1000+(1000-ROW())/10000000,-1) -> -1
A9: YANKEE | B9: pvt_rgz_gkohla.ftth | C9: 36 | D9: =IF(C9>0,C9/Paramètres!$B$5,"") -> 1.6363636 | E9: 1 | F9: =IF(C9>0,E9/D9,"") -> 0.61111111 | G9: =IF(C9>0,IF(E9>=D9,"Oui","Non"),"Sans objectif") -> Non | H9: =IF(AND(L9>0,L9=MAX($L$5:$L$48)),"Champion","") | I9: =IF(G9="Oui",Paramètres!$B$6,0) -> 0 | J9: =IF(H9="Champion",Paramètres!$B$7,0) -> 0 | K9: =I9+J9 -> 0 | L9: =IF(G9="Oui",F9+E9/1000+(1000-ROW())/10000000,-1) -> -1
A10: YANKEE | B10: pvt_rgz_rclotoe.ftth | C10: 30 | D10: =IF(C10>0,C10/Paramètres!$B$5,"") -> 1.3636364 | E10: 1 | F10: =IF(C10>0,E10/D10,"") -> 0.73333333 | G10: =IF(C10>0,IF(E10>=D10,"Oui","Non"),"Sans objectif") -> Non | H10: =IF(AND(L10>0,L10=MAX($L$5:$L$48)),"Champion","") | I10: =IF(G10="Oui",Paramètres!$B$6,0) -> 0 | J10: =IF(H10="Champion",Paramètres!$B$7,0) -> 0 | K10: =I10+J10 -> 0 | L10: =IF(G10="Oui",F10+E10/1000+(1000-ROW())/10000000,-1) -> -1
A11: YANKEE | B11: pvt_rgz_aconstant.ftth | C11: 25 | D11: =IF(C11>0,C11/Paramètres!$B$5,"") -> 1.1363636 | E11: 9 | F11: =IF(C11>0,E11/D11,"") -> 7.92 | G11: =IF(C11>0,IF(E11>=D11,"Oui","Non"),"Sans objectif") -> Oui | H11: =IF(AND(L11>0,L11=MAX($L$5:$L$48)),"Champion","") -> Champion | I11: =IF(G11="Oui",Paramètres!$B$6,0) -> 200 | J11: =IF(H11="Champion",Paramètres!$B$7,0) -> 1000 | K11: =I11+J11 -> 1200 | L11: =IF(G11="Oui",F11+E11/1000+(1000-ROW())/10000000,-1) -> 7.9290989
A12: YANKEE | B12: pvt_rgz_cmessinou.ftth | C12: 23 | D12: =IF(C12>0,C12/Paramètres!$B$5,"") -> 1.0454545 | E12: 4 | F12: =IF(C12>0,E12/D12,"") -> 3.826087 | G12: =IF(C12>0,IF(E12>=D12,"Oui","Non"),"Sans objectif") -> Oui | H12: =IF(AND(L12>0,L12=MAX($L$5:$L$48)),"Champion","") | I12: =IF(G12="Oui",Paramètres!$B$6,0) -> 200 | J12: =IF(H12="Champion",Paramètres!$B$7,0) -> 0 | K12: =I12+J12 -> 200 | L12: =IF(G12="Oui",F12+E12/1000+(1000-ROW())/10000000,-1) -> 3.8301858
A13: YANKEE | B13: pvt_rgz_lsenakpon.ftth | C13: 40 | D13: =IF(C13>0,C13/Paramètres!$B$5,"") -> 1.8181818 | E13: 1 | F13: =IF(C13>0,E13/D13,"") -> 0.55 | G13: =IF(C13>0,IF(E13>=D13,"Oui","Non"),"Sans objectif") -> Non | H13: =IF(AND(L13>0,L13=MAX($L$5:$L$48)),"Champion","") | I13: =IF(G13="Oui",Paramètres!$B$6,0) -> 0 | J13: =IF(H13="Champion",Paramètres!$B$7,0) -> 0 | K13: =I13+J13 -> 0 | L13: =IF(G13="Oui",F13+E13/1000+(1000-ROW())/10000000,-1) -> -1
A14: YANKEE | B14: pvt_rgz_tletitia.ftth | C14: 20 | D14: =IF(C14>0,C14/Paramètres!$B$5,"") -> 0.90909091 | E14: 0 | F14: =IF(C14>0,E14/D14,"") -> 0 | G14: =IF(C14>0,IF(E14>=D14,"Oui","Non"),"Sans objectif") -> Non | H14: =IF(AND(L14>0,L14=MAX($L$5:$L$48)),"Champion","") | I14: =IF(G14="Oui",Paramètres!$B$6,0) -> 0 | J14: =IF(H14="Champion",Paramètres!$B$7,0) -> 0 | K14: =I14+J14 -> 0 | L14: =IF(G14="Oui",F14+E14/1000+(1000-ROW())/10000000,-1) -> -1
A15: YANKEE | B15: pvt_rgz_dalexis.ftth | C15: 15 | D15: =IF(C15>0,C15/Paramètres!$B$5,"") -> 0.68181818 | E15: 0 | F15: =IF(C15>0,E15/D15,"") -> 0 | G15: =IF(C15>0,IF(E15>=D15,"Oui","Non"),"Sans objectif") -> Non | H15: =IF(AND(L15>0,L15=MAX($L$5:$L$48)),"Champion","") | I15: =IF(G15="Oui",Paramètres!$B$6,0) -> 0 | J15: =IF(H15="Champion",Paramètres!$B$7,0) -> 0 | K15: =I15+J15 -> 0 | L15: =IF(G15="Oui",F15+E15/1000+(1000-ROW())/10000000,-1) -> -1
A16: YANKEE | B16: pvt_rgz_eulisse.ftth | C16: 10 | D16: =IF(C16>0,C16/Paramètres!$B$5,"") -> 0.45454545 | E16: 0 | F16: =IF(C16>0,E16/D16,"") -> 0 | G16: =IF(C16>0,IF(E16>=D16,"Oui","Non"),"Sans objectif") -> Non | H16: =IF(AND(L16>0,L16=MAX($L$5:$L$48)),"Champion","") | I16: =IF(G16="Oui",Paramètres!$B$6,0) -> 0 | J16: =IF(H16="Champion",Paramètres!$B$7,0) -> 0 | K16: =I16+J16 -> 0 | L16: =IF(G16="Oui",F16+E16/1000+(1000-ROW())/10000000,-1) -> -1
A17: YANKEE | B17: pvt_rgz_hgilles.ftth | D17: =IF(C17>0,C17/Paramètres!$B$5,"") | E17: 0 | F17: =IF(C17>0,E17/D17,"") | G17: =IF(C17>0,IF(E17>=D17,"Oui","Non"),"Sans objectif") -> Sans objectif | H17: =IF(AND(L17>0,L17=MAX($L$5:$L$48)),"Champion","") | I17: =IF(G17="Oui",Paramètres!$B$6,0) -> 0 | J17: =IF(H17="Champion",Paramètres!$B$7,0) -> 0 | K17: =I17+J17 -> 0 | L17: =IF(G17="Oui",F17+E17/1000+(1000-ROW())/10000000,-1) -> -1
A18: ALPHA | B18: pms_rgz_tgloria.ftth | C18: 53 | D18: =IF(C18>0,C18/Paramètres!$B$5,"") -> 2.4090909 | E18: 0 | F18: =IF(C18>0,E18/D18,"") -> 0 | G18: =IF(C18>0,IF(E18>=D18,"Oui","Non"),"Sans objectif") -> Non | H18: =IF(AND(L18>0,L18=MAX($L$5:$L$48)),"Champion","") | I18: =IF(G18="Oui",Paramètres!$B$6,0) -> 0 | J18: =IF(H18="Champion",Paramètres!$B$7,0) -> 0 | K18: =I18+J18 -> 0 | L18: =IF(G18="Oui",F18+E18/1000+(1000-ROW())/10000000,-1) -> -1
A19: ALPHA | B19: pms_rgz_dconstant.ftth | C19: 29 | D19: =IF(C19>0,C19/Paramètres!$B$5,"") -> 1.3181818 | E19: 1 | F19: =IF(C19>0,E19/D19,"") -> 0.75862069 | G19: =IF(C19>0,IF(E19>=D19,"Oui","Non"),"Sans objectif") -> Non | H19: =IF(AND(L19>0,L19=MAX($L$5:$L$48)),"Champion","") | I19: =IF(G19="Oui",Paramètres!$B$6,0) -> 0 | J19: =IF(H19="Champion",Paramètres!$B$7,0) -> 0 | K19: =I19+J19 -> 0 | L19: =IF(G19="Oui",F19+E19/1000+(1000-ROW())/10000000,-1) -> -1
A20: ALPHA | B20: pvt_rgz_bboris.ftth | C20: 18 | D20: =IF(C20>0,C20/Paramètres!$B$5,"") -> 0.81818182 | E20: 1 | F20: =IF(C20>0,E20/D20,"") -> 1.2222222 | G20: =IF(C20>0,IF(E20>=D20,"Oui","Non"),"Sans objectif") -> Oui | H20: =IF(AND(L20>0,L20=MAX($L$5:$L$48)),"Champion","") | I20: =IF(G20="Oui",Paramètres!$B$6,0) -> 200 | J20: =IF(H20="Champion",Paramètres!$B$7,0) -> 0 | K20: =I20+J20 -> 200 | L20: =IF(G20="Oui",F20+E20/1000+(1000-ROW())/10000000,-1) -> 1.2233202
A21: TANGO | B21: pvt_rgz_dthibaut.ftth | C21: 62 | D21: =IF(C21>0,C21/Paramètres!$B$5,"") -> 2.8181818 | E21: 1 | F21: =IF(C21>0,E21/D21,"") -> 0.35483871 | G21: =IF(C21>0,IF(E21>=D21,"Oui","Non"),"Sans objectif") -> Non | H21: =IF(AND(L21>0,L21=MAX($L$5:$L$48)),"Champion","") | I21: =IF(G21="Oui",Paramètres!$B$6,0) -> 0 | J21: =IF(H21="Champion",Paramètres!$B$7,0) -> 0 | K21: =I21+J21 -> 0 | L21: =IF(G21="Oui",F21+E21/1000+(1000-ROW())/10000000,-1) -> -1
A22: TANGO | B22: pms_rgz_hfrancine.ftth | C22: 50 | D22: =IF(C22>0,C22/Paramètres!$B$5,"") -> 2.2727273 | E22: 2 | F22: =IF(C22>0,E22/D22,"") -> 0.88 | G22: =IF(C22>0,IF(E22>=D22,"Oui","Non"),"Sans objectif") -> Non | H22: =IF(AND(L22>0,L22=MAX($L$5:$L$48)),"Champion","") | I22: =IF(G22="Oui",Paramètres!$B$6,0) -> 0 | J22: =IF(H22="Champion",Paramètres!$B$7,0) -> 0 | K22: =I22+J22 -> 0 | L22: =IF(G22="Oui",F22+E22/1000+(1000-ROW())/10000000,-1) -> -1
A23: TANGO | B23: pvt_rgz_wdiane.ftth | C23: 51 | D23: =IF(C23>0,C23/Paramètres!$B$5,"") -> 2.3181818 | E23: 1 | F23: =IF(C23>0,E23/D23,"") -> 0.43137255 | G23: =IF(C23>0,IF(E23>=D23,"Oui","Non"),"Sans objectif") -> Non | H23: =IF(AND(L23>0,L23=MAX($L$5:$L$48)),"Champion","") | I23: =IF(G23="Oui",Paramètres!$B$6,0) -> 0 | J23: =IF(H23="Champion",Paramètres!$B$7,0) -> 0 | K23: =I23+J23 -> 0 | L23: =IF(G23="Oui",F23+E23/1000+(1000-ROW())/10000000,-1) -> -1
A24: TANGO | B24: pvt_rgz_gsahoui.ftth | C24: 47 | D24: =IF(C24>0,C24/Paramètres!$B$5,"") -> 2.1363636 | E24: 0 | F24: =IF(C24>0,E24/D24,"") -> 0 | G24: =IF(C24>0,IF(E24>=D24,"Oui","Non"),"Sans objectif") -> Non | H24: =IF(AND(L24>0,L24=MAX($L$5:$L$48)),"Champion","") | I24: =IF(G24="Oui",Paramètres!$B$6,0) -> 0 | J24: =IF(H24="Champion",Paramètres!$B$7,0) -> 0 | K24: =I24+J24 -> 0 | L24: =IF(G24="Oui",F24+E24/1000+(1000-ROW())/10000000,-1) -> -1
A25: ZULU | B25: pvt-rgz-olouis.ftth | C25: 60 | D25: =IF(C25>0,C25/Paramètres!$B$5,"") -> 2.7272727 | E25: 0 | F25: =IF(C25>0,E25/D25,"") -> 0 | G25: =IF(C25>0,IF(E25>=D25,"Oui","Non"),"Sans objectif") -> Non | H25: =IF(AND(L25>0,L25=MAX($L$5:$L$48)),"Champion","") | I25: =IF(G25="Oui",Paramètres!$B$6,0) -> 0 | J25: =IF(H25="Champion",Paramètres!$B$7,0) -> 0 | K25: =I25+J25 -> 0 | L25: =IF(G25="Oui",F25+E25/1000+(1000-ROW())/10000000,-1) -> -1
A26: ZULU | B26: pvt_rgz_ahugues.ftth | C26: 60 | D26: =IF(C26>0,C26/Paramètres!$B$5,"") -> 2.7272727 | E26: 3 | F26: =IF(C26>0,E26/D26,"") -> 1.1 | G26: =IF(C26>0,IF(E26>=D26,"Oui","Non"),"Sans objectif") -> Oui | H26: =IF(AND(L26>0,L26=MAX($L$5:$L$48)),"Champion","") | I26: =IF(G26="Oui",Paramètres!$B$6,0) -> 200 | J26: =IF(H26="Champion",Paramètres!$B$7,0) -> 0 | K26: =I26+J26 -> 200 | L26: =IF(G26="Oui",F26+E26/1000+(1000-ROW())/10000000,-1) -> 1.1030974
A27: ZULU | B27: pvt_rgz_adidier.ftth | D27: =IF(C27>0,C27/Paramètres!$B$5,"") | E27: 0 | F27: =IF(C27>0,E27/D27,"") | G27: =IF(C27>0,IF(E27>=D27,"Oui","Non"),"Sans objectif") -> Sans objectif | H27: =IF(AND(L27>0,L27=MAX($L$5:$L$48)),"Champion","") | I27: =IF(G27="Oui",Paramètres!$B$6,0) -> 0 | J27: =IF(H27="Champion",Paramètres!$B$7,0) -> 0 | K27: =I27+J27 -> 0 | L27: =IF(G27="Oui",F27+E27/1000+(1000-ROW())/10000000,-1) -> -1
A28: CHARLIE | B28: pms_rgz_wmarius.ftth | C28: 45 | D28: =IF(C28>0,C28/Paramètres!$B$5,"") -> 2.0454545 | E28: 0 | F28: =IF(C28>0,E28/D28,"") -> 0 | G28: =IF(C28>0,IF(E28>=D28,"Oui","Non"),"Sans objectif") -> Non | H28: =IF(AND(L28>0,L28=MAX($L$5:$L$48)),"Champion","") | I28: =IF(G28="Oui",Paramètres!$B$6,0) -> 0 | J28: =IF(H28="Champion",Paramètres!$B$7,0) -> 0 | K28: =I28+J28 -> 0 | L28: =IF(G28="Oui",F28+E28/1000+(1000-ROW())/10000000,-1) -> -1
A29: CHARLIE | B29: pvt_rgz_tsylvia.ftth | C29: 35 | D29: =IF(C29>0,C29/Paramètres!$B$5,"") -> 1.5909091 | E29: 0 | F29: =IF(C29>0,E29/D29,"") -> 0 | G29: =IF(C29>0,IF(E29>=D29,"Oui","Non"),"Sans objectif") -> Non | H29: =IF(AND(L29>0,L29=MAX($L$5:$L$48)),"Champion","") | I29: =IF(G29="Oui",Paramètres!$B$6,0) -> 0 | J29: =IF(H29="Champion",Paramètres!$B$7,0) -> 0 | K29: =I29+J29 -> 0 | L29: =IF(G29="Oui",F29+E29/1000+(1000-ROW())/10000000,-1) -> -1
A30: MIKE | B30: pvt_rgz_oalain.ftth | C30: 31 | D30: =IF(C30>0,C30/Paramètres!$B$5,"") -> 1.4090909 | E30: 0 | F30: =IF(C30>0,E30/D30,"") -> 0 | G30: =IF(C30>0,IF(E30>=D30,"Oui","Non"),"Sans objectif") -> Non | H30: =IF(AND(L30>0,L30=MAX($L$5:$L$48)),"Champion","") | I30: =IF(G30="Oui",Paramètres!$B$6,0) -> 0 | J30: =IF(H30="Champion",Paramètres!$B$7,0) -> 0 | K30: =I30+J30 -> 0 | L30: =IF(G30="Oui",F30+E30/1000+(1000-ROW())/10000000,-1) -> -1
A31: MIKE | B31: pvt_rgz_sulrich.ftth | C31: 45 | D31: =IF(C31>0,C31/Paramètres!$B$5,"") -> 2.0454545 | E31: 0 | F31: =IF(C31>0,E31/D31,"") -> 0 | G31: =IF(C31>0,IF(E31>=D31,"Oui","Non"),"Sans objectif") -> Non | H31: =IF(AND(L31>0,L31=MAX($L$5:$L$48)),"Champion","") | I31: =IF(G31="Oui",Paramètres!$B$6,0) -> 0 | J31: =IF(H31="Champion",Paramètres!$B$7,0) -> 0 | K31: =I31+J31 -> 0 | L31: =IF(G31="Oui",F31+E31/1000+(1000-ROW())/10000000,-1) -> -1
A32: MIKE | B32: pvt_rgz_hderrick.ftth | C32: 32 | D32: =IF(C32>0,C32/Paramètres!$B$5,"") -> 1.4545455 | E32: 0 | F32: =IF(C32>0,E32/D32,"") -> 0 | G32: =IF(C32>0,IF(E32>=D32,"Oui","Non"),"Sans objectif") -> Non | H32: =IF(AND(L32>0,L32=MAX($L$5:$L$48)),"Champion","") | I32: =IF(G32="Oui",Paramètres!$B$6,0) -> 0 | J32: =IF(H32="Champion",Paramètres!$B$7,0) -> 0 | K32: =I32+J32 -> 0 | L32: =IF(G32="Oui",F32+E32/1000+(1000-ROW())/10000000,-1) -> -1
A33: MIKE | B33: pms_rgz_kromeo.ftth | C33: 22 | D33: =IF(C33>0,C33/Paramètres!$B$5,"") -> 1 | E33: 0 | F33: =IF(C33>0,E33/D33,"") -> 0 | G33: =IF(C33>0,IF(E33>=D33,"Oui","Non"),"Sans objectif") -> Non | H33: =IF(AND(L33>0,L33=MAX($L$5:$L$48)),"Champion","") | I33: =IF(G33="Oui",Paramètres!$B$6,0) -> 0 | J33: =IF(H33="Champion",Paramètres!$B$7,0) -> 0 | K33: =I33+J33 -> 0 | L33: =IF(G33="Oui",F33+E33/1000+(1000-ROW())/10000000,-1) -> -1
A34: ANONYMAT | B34: pvt_rgz_gprince.ftth | C34: 35 | D34: =IF(C34>0,C34/Paramètres!$B$5,"") -> 1.5909091 | E34: 3 | F34: =IF(C34>0,E34/D34,"") -> 1.8857143 | G34: =IF(C34>0,IF(E34>=D34,"Oui","Non"),"Sans objectif") -> Oui | H34: =IF(AND(L34>0,L34=MAX($L$5:$L$48)),"Champion","") | I34: =IF(G34="Oui",Paramètres!$B$6,0) -> 200 | J34: =IF(H34="Champion",Paramètres!$B$7,0) -> 0 | K34: =I34+J34 -> 200 | L34: =IF(G34="Oui",F34+E34/1000+(1000-ROW())/10000000,-1) -> 1.8888109
A35: ANONYMAT | B35: pvt_rgz_akoffi.ftth | C35: 35 | D35: =IF(C35>0,C35/Paramètres!$B$5,"") -> 1.5909091 | E35: 9 | F35: =IF(C35>0,E35/D35,"") -> 5.6571429 | G35: =IF(C35>0,IF(E35>=D35,"Oui","Non"),"Sans objectif") -> Oui | H35: =IF(AND(L35>0,L35=MAX($L$5:$L$48)),"Champion","") | I35: =IF(G35="Oui",Paramètres!$B$6,0) -> 200 | J35: =IF(H35="Champion",Paramètres!$B$7,0) -> 0 | K35: =I35+J35 -> 200 | L35: =IF(G35="Oui",F35+E35/1000+(1000-ROW())/10000000,-1) -> 5.6662394
A36: ANONYMAT | B36: pvt_rgz_agado.ftth | C36: 35 | D36: =IF(C36>0,C36/Paramètres!$B$5,"") -> 1.5909091 | E36: 0 | F36: =IF(C36>0,E36/D36,"") -> 0 | G36: =IF(C36>0,IF(E36>=D36,"Oui","Non"),"Sans objectif") -> Non | H36: =IF(AND(L36>0,L36=MAX($L$5:$L$48)),"Champion","") | I36: =IF(G36="Oui",Paramètres!$B$6,0) -> 0 | J36: =IF(H36="Champion",Paramètres!$B$7,0) -> 0 | K36: =I36+J36 -> 0 | L36: =IF(G36="Oui",F36+E36/1000+(1000-ROW())/10000000,-1) -> -1
A37: ANONYMAT | B37: pvt_rgz_lcedric.ftth | C37: 35 | D37: =IF(C37>0,C37/Paramètres!$B$5,"") -> 1.5909091 | E37: 0 | F37: =IF(C37>0,E37/D37,"") -> 0 | G37: =IF(C37>0,IF(E37>=D37,"Oui","Non"),"Sans objectif") -> Non | H37: =IF(AND(L37>0,L37=MAX($L$5:$L$48)),"Champion","") | I37: =IF(G37="Oui",Paramètres!$B$6,0) -> 0 | J37: =IF(H37="Champion",Paramètres!$B$7,0) -> 0 | K37: =I37+J37 -> 0 | L37: =IF(G37="Oui",F37+E37/1000+(1000-ROW())/10000000,-1) -> -1
A38: CONCORDE | B38: pvt_rgz_kbernadin.ftth | C38: 40 | D38: =IF(C38>0,C38/Paramètres!$B$5,"") -> 1.8181818 | E38: 0 | F38: =IF(C38>0,E38/D38,"") -> 0 | G38: =IF(C38>0,IF(E38>=D38,"Oui","Non"),"Sans objectif") -> Non | H38: =IF(AND(L38>0,L38=MAX($L$5:$L$48)),"Champion","") | I38: =IF(G38="Oui",Paramètres!$B$6,0) -> 0 | J38: =IF(H38="Champion",Paramètres!$B$7,0) -> 0 | K38: =I38+J38 -> 0 | L38: =IF(G38="Oui",F38+E38/1000+(1000-ROW())/10000000,-1) -> -1
A39: CONCORDE | B39: pms_rgz_cmerveille.ftth | C39: 31 | D39: =IF(C39>0,C39/Paramètres!$B$5,"") -> 1.4090909 | E39: 1 | F39: =IF(C39>0,E39/D39,"") -> 0.70967742 | G39: =IF(C39>0,IF(E39>=D39,"Oui","Non"),"Sans objectif") -> Non | H39: =IF(AND(L39>0,L39=MAX($L$5:$L$48)),"Champion","") | I39: =IF(G39="Oui",Paramètres!$B$6,0) -> 0 | J39: =IF(H39="Champion",Paramètres!$B$7,0) -> 0 | K39: =I39+J39 -> 0 | L39: =IF(G39="Oui",F39+E39/1000+(1000-ROW())/10000000,-1) -> -1
... A47: OMEGA | B47: pvt_rgz_ojeovani.ftth | C47: 30 | D47: =IF(C47>0,C47/Paramètres!$B$5,"") -> 1.3636364 | E47: 0 | F47: =IF(C47>0,E47/D47,"") -> 0 | G47: =IF(C47>0,IF(E47>=D47,"Oui","Non"),"Sans objectif") -> Non | H47: =IF(AND(L47>0,L47=MAX($L$5:$L$48)),"Champion","") | I47: =IF(G47="Oui",Paramètres!$B$6,0) -> 0 | J47: =IF(H47="Champion",Paramètres!$B$7,0) -> 0 | K47: =I47+J47 -> 0 | L47: =IF(G47="Oui",F47+E47/1000+(1000-ROW())/10000000,-1) -> -1
A48: À préciser | B48: pvt_rgz_smireille.ftth | D48: =IF(C48>0,C48/Paramètres!$B$5,"") | E48: 1 | F48: =IF(C48>0,E48/D48,"") | G48: =IF(C48>0,IF(E48>=D48,"Oui","Non"),"Sans objectif") -> Sans objectif | H48: =IF(AND(L48>0,L48=MAX($L$5:$L$48)),"Champion","") | I48: =IF(G48="Oui",Paramètres!$B$6,0) -> 0 | J48: =IF(H48="Champion",Paramètres!$B$7,0) -> 0 | K48: =I48+J48 -> 0 | L48: =IF(G48="Oui",F48+E48/1000+(1000-ROW())/10000000,-1) -> -1
...

Sheet Équipes 12-10
A1: Équipes : performance du 12 octobre
A2: Une journée équipe est réussie quand les ventes de l'équipe atteignent son objectif du jour.
A4: Équipe | B4: Obj. du mois | C4: Obj. du jour | D4: Ventes du jour | E4: Réalisation | F4: Journée équipe réussie | G4: Agents avec objectif | H4: Agents ayant vendu | I4: Agents à objectif atteint | J4: Prime superviseur (FCFA)
A5: YANKEE | B5: =SUMIF('Agents 12-10'!$A$5:$A$48,A5,'Agents 12-10'!$C$5:$C$48) -> 340 | C5: =B5/Paramètres!$B$5 -> 15.454545 | D5: =SUMIF('Agents 12-10'!$A$5:$A$48,A5,'Agents 12-10'!$E$5:$E$48) -> 19 | E5: =IF(C5>0,D5/C5,"") -> 1.2294118 | F5: =IF(D5>=C5,"Oui","Non") -> Oui | G5: =COUNTIFS('Agents 12-10'!$A$5:$A$48,A5,'Agents 12-10'!$C$5:$C$48,">0") -> 12 | H5: =COUNTIFS('Agents 12-10'!$A$5:$A$48,A5,'Agents 12-10'!$E$5:$E$48,">0") -> 6 | I5: =COUNTIFS('Agents 12-10'!$A$5:$A$48,A5,'Agents 12-10'!$G$5:$G$48,"Oui") -> 3 | J5: =IF(F5="Oui",Paramètres!$B$8,0) -> 500
A6: ALPHA | B6: =SUMIF('Agents 12-10'!$A$5:$A$48,A6,'Agents 12-10'!$C$5:$C$48) -> 100 | C6: =B6/Paramètres!$B$5 -> 4.5454545 | D6: =SUMIF('Agents 12-10'!$A$5:$A$48,A6,'Agents 12-10'!$E$5:$E$48) -> 2 | E6: =IF(C6>0,D6/C6,"") -> 0.44 | F6: =IF(D6>=C6,"Oui","Non") -> Non | G6: =COUNTIFS('Agents 12-10'!$A$5:$A$48,A6,'Agents 12-10'!$C$5:$C$48,">0") -> 3 | H6: =COUNTIFS('Agents 12-10'!$A$5:$A$48,A6,'Agents 12-10'!$E$5:$E$48,">0") -> 2 | I6: =COUNTIFS('Agents 12-10'!$A$5:$A$48,A6,'Agents 12-10'!$G$5:$G$48,"Oui") -> 1 | J6: =IF(F6="Oui",Paramètres!$B$8,0) -> 0
A7: TANGO | B7: =SUMIF('Agents 12-10'!$A$5:$A$48,A7,'Agents 12-10'!$C$5:$C$48) -> 210 | C7: =B7/Paramètres!$B$5 -> 9.5454545 | D7: =SUMIF('Agents 12-10'!$A$5:$A$48,A7,'Agents 12-10'!$E$5:$E$48) -> 4 | E7: =IF(C7>0,D7/C7,"") -> 0.41904762 | F7: =IF(D7>=C7,"Oui","Non") -> Non | G7: =COUNTIFS('Agents 12-10'!$A$5:$A$48,A7,'Agents 12-10'!$C$5:$C$48,">0") -> 4 | H7: =COUNTIFS('Agents 12-10'!$A$5:$A$48,A7,'Agents 12-10'!$E$5:$E$48,">0") -> 3 | I7: =COUNTIFS('Agents 12-10'!$A$5:$A$48,A7,'Agents 12-10'!$G$5:$G$48,"Oui") -> 0 | J7: =IF(F7="Oui",Paramètres!$B$8,0) -> 0
A8: ZULU | B8: =SUMIF('Agents 12-10'!$A$5:$A$48,A8,'Agents 12-10'!$C$5:$C$48) -> 120 | C8: =B8/Paramètres!$B$5 -> 5.4545455 | D8: =SUMIF('Agents 12-10'!$A$5:$A$48,A8,'Agents 12-10'!$E$5:$E$48) -> 3 | E8: =IF(C8>0,D8/C8,"") -> 0.55 | F8: =IF(D8>=C8,"Oui","Non") -> Non | G8: =COUNTIFS('Agents 12-10'!$A$5:$A$48,A8,'Agents 12-10'!$C$5:$C$48,">0") -> 2 | H8: =COUNTIFS('Agents 12-10'!$A$5:$A$48,A8,'Agents 12-10'!$E$5:$E$48,">0") -> 1 | I8: =COUNTIFS('Agents 12-10'!$A$5:$A$48,A8,'Agents 12-10'!$G$5:$G$48,"Oui") -> 1 | J8: =IF(F8="Oui",Paramètres!$B$8,0) -> 0
A9: CHARLIE | B9: =SUMIF('Agents 12-10'!$A$5:$A$48,A9,'Agents 12-10'!$C$5:$C$48) -> 80 | C9: =B9/Paramètres!$B$5 -> 3.6363636 | D9: =SUMIF('Agents 12-10'!$A$5:$A$48,A9,'Agents 12-10'!$E$5:$E$48) -> 0 | E9: =IF(C9>0,D9/C9,"") -> 0 | F9: =IF(D9>=C9,"Oui","Non") -> Non | G9: =COUNTIFS('Agents 12-10'!$A$5:$A$48,A9,'Agents 12-10'!$C$5:$C$48,">0") -> 2 | H9: =COUNTIFS('Agents 12-10'!$A$5:$A$48,A9,'Agents 12-10'!$E$5:$E$48,">0") -> 0 | I9: =COUNTIFS('Agents 12-10'!$A$5:$A$48,A9,'Agents 12-10'!$G$5:$G$48,"Oui") -> 0 | J9: =IF(F9="Oui",Paramètres!$B$8,0) -> 0
A10: MIKE | B10: =SUMIF('Agents 12-10'!$A$5:$A$48,A10,'Agents 12-10'!$C$5:$C$48) -> 130 | C10: =B10/Paramètres!$B$5 -> 5.9090909 | D10: =SUMIF('Agents 12-10'!$A$5:$A$48,A10,'Agents 12-10'!$E$5:$E$48) -> 0 | E10: =IF(C10>0,D10/C10,"") -> 0 | F10: =IF(D10>=C10,"Oui","Non") -> Non | G10: =COUNTIFS('Agents 12-10'!$A$5:$A$48,A10,'Agents 12-10'!$C$5:$C$48,">0") -> 4 | H10: =COUNTIFS('Agents 12-10'!$A$5:$A$48,A10,'Agents 12-10'!$E$5:$E$48,">0") -> 0 | I10: =COUNTIFS('Agents 12-10'!$A$5:$A$48,A10,'Agents 12-10'!$G$5:$G$48,"Oui") -> 0 | J10: =IF(F10="Oui",Paramètres!$B$8,0) -> 0
A11: ANONYMAT | B11: =SUMIF('Agents 12-10'!$A$5:$A$48,A11,'Agents 12-10'!$C$5:$C$48) -> 140 | C11: =B11/Paramètres!$B$5 -> 6.3636364 | D11: =SUMIF('Agents 12-10'!$A$5:$A$48,A11,'Agents 12-10'!$E$5:$E$48) -> 12 | E11: =IF(C11>0,D11/C11,"") -> 1.8857143 | F11: =IF(D11>=C11,"Oui","Non") -> Oui | G11: =COUNTIFS('Agents 12-10'!$A$5:$A$48,A11,'Agents 12-10'!$C$5:$C$48,">0") -> 4 | H11: =COUNTIFS('Agents 12-10'!$A$5:$A$48,A11,'Agents 12-10'!$E$5:$E$48,">0") -> 2 | I11: =COUNTIFS('Agents 12-10'!$A$5:$A$48,A11,'Agents 12-10'!$G$5:$G$48,"Oui") -> 2 | J11: =IF(F11="Oui",Paramètres!$B$8,0) -> 500
A12: CONCORDE | B12: =SUMIF('Agents 12-10'!$A$5:$A$48,A12,'Agents 12-10'!$C$5:$C$48) -> 167 | C12: =B12/Paramètres!$B$5 -> 7.5909091 | D12: =SUMIF('Agents 12-10'!$A$5:$A$48,A12,'Agents 12-10'!$E$5:$E$48) -> 3 | E12: =IF(C12>0,D12/C12,"") -> 0.39520958 | F12: =IF(D12>=C12,"Oui","Non") -> Non | G12: =COUNTIFS('Agents 12-10'!$A$5:$A$48,A12,'Agents 12-10'!$C$5:$C$48,">0") -> 5 | H12: =COUNTIFS('Agents 12-10'!$A$5:$A$48,A12,'Agents 12-10'!$E$5:$E$48,">0") -> 3 | I12: =COUNTIFS('Agents 12-10'!$A$5:$A$48,A12,'Agents 12-10'!$G$5:$G$48,"Oui") -> 0 | J12: =IF(F12="Oui",Paramètres!$B$8,0) -> 0
A13: BRAVO | B13: =SUMIF('Agents 12-10'!$A$5:$A$48,A13,'Agents 12-10'!$C$5:$C$48) -> 100 | C13: =B13/Paramètres!$B$5 -> 4.5454545 | D13: =SUMIF('Agents 12-10'!$A$5:$A$48,A13,'Agents 12-10'!$E$5:$E$48) -> 0 | E13: =IF(C13>0,D13/C13,"") -> 0 | F13: =IF(D13>=C13,"Oui","Non") -> Non | G13: =COUNTIFS('Agents 12-10'!$A$5:$A$48,A13,'Agents 12-10'!$C$5:$C$48,">0") -> 2 | H13: =COUNTIFS('Agents 12-10'!$A$5:$A$48,A13,'Agents 12-10'!$E$5:$E$48,">0") -> 0 | I13: =COUNTIFS('Agents 12-10'!$A$5:$A$48,A13,'Agents 12-10'!$G$5:$G$48,"Oui") -> 0 | J13: =IF(F13="Oui",Paramètres!$B$8,0) -> 0
A14: OMEGA | B14: =SUMIF('Agents 12-10'!$A$5:$A$48,A14,'Agents 12-10'!$C$5:$C$48) -> 100 | C14: =B14/Paramètres!$B$5 -> 4.5454545 | D14: =SUMIF('Agents 12-10'!$A$5:$A$48,A14,'Agents 12-10'!$E$5:$E$48) -> 1 | E14: =IF(C14>0,D14/C14,"") -> 0.22 | F14: =IF(D14>=C14,"Oui","Non") -> Non | G14: =COUNTIFS('Agents 12-10'!$A$5:$A$48,A14,'Agents 12-10'!$C$5:$C$48,">0") -> 3 | H14: =COUNTIFS('Agents 12-10'!$A$5:$A$48,A14,'Agents 12-10'!$E$5:$E$48,">0") -> 1 | I14: =COUNTIFS('Agents 12-10'!$A$5:$A$48,A14,'Agents 12-10'!$G$5:$G$48,"Oui") -> 0 | J14: =IF(F14="Oui",Paramètres!$B$8,0) -> 0
A15: RÉSEAU | B15: =SUM(B5:B14) -> 1487 | C15: =SUM(C5:C14) -> 67.590909 | D15: =SUM(D5:D14) -> 44 | E15: =IF(C15>0,'Agents 12-10'!E49/C15,"") -> 0.66577001 | G15: =SUM(G5:G14) -> 41 | H15: =SUM(H5:H14) -> 18 | I15: =SUM(I5:I14) -> 7 | J15: =SUM(J5:J14) -> 1000

Sheet Points d'attention
A1: Points d'attention du 12 octobre
A2: Constats et actions proposées.
A4: Sujet | B4: Constat | C4: Action proposée
A5: Équipes à zéro | B5: CHARLIE, MIKE et BRAVO n'ont aucune vente un lundi. BRAVO porte 40 des 240 ventes B2B du mois. | C5: Appeler les trois superviseurs en priorité.
A6: Journées à 9 ventes | B6: aconstant (objectif 25 sur le mois) et akoffi ont fait 9 ventes chacun. Pour aconstant, c'est plus du tiers de l'objectif mensuel en une journée. | C6: Vérifier qu'il s'agit de ventes du jour et non d'activations accumulées validées d'un coup, avant d'annoncer le champion.
A7: Login inconnu | B7: pvt_rgz_smireille.ftth a 1 vente mais n'a ni équipe ni objectif. | C7: Préciser son équipe. Sans objectif, il est suivi mais n'a pas droit aux primes.
A8: Écart de logins | B8: Le rapport Celtiis écrit pvt_rgz_amarcel.ftth, le fichier d'objectifs pvt_rgz_amarcel. pvt_rgz_mvenceslas est probablement dans le même cas. | C8: Harmoniser les logins, sinon le rapprochement dans Power BI échouera.
A9: Détail B2C/B2B | B9: Le point du jour ne donne que le total des ventes. | C9: Demander la répartition B2C/B2B pour suivre le bonus B2B.
A10: Objectif du jour | B10: Calculé sur 22 jours ouvrés (lundi à vendredi). Le fichier d'objectifs divise par 20, ce qui donne des objectifs journaliers plus élevés. | C10: Garder une seule convention pour tout le mois.

Sheet Message WhatsApp
A1: Message pour le groupe WhatsApp
A2: Texte prêt à copier (rédigé à partir des chiffres du 12 octobre).
A4: Point du lundi 12 octobre : 45 ventes, 67 % de l'objectif du jour.
A5: Champion du jour : aconstant (YANKEE), 9 ventes. Bravo aussi à akoffi, cmessinou, gprince, mfrancois, bboris et ahugues, qui ont tous tenu leur objectif.
A6: Équipes au-dessus de l'objectif : ANONYMAT (189 %) et YANKEE (123 %).
A7: CHARLIE, MIKE et BRAVO, on vous attend demain.
